Workbook

Sheet Dashboard
B3: NPV & ROI Advanced Investment Calculator
B4: Evaluate any project with institutional-grade financial rigour | Hurdle Rate: 12% ROI
B5: Built by Akshay K Kothari, CA · FP&A Consultant · askakshay.com
B11: COLOUR CODING GUIDE
B12: Input cells (blue) — change freely | C12: Formulas (black) — do not edit | D12: Cross-sheet links (green) | E12: ⚠ Highlighted assumptions | F12: ✅ Invest / ❌ Don't invest
B14: WORKSHEET NAVIGATOR
B15: 1. Assumptions | C15: Project inputs: investment, revenue, costs, discount rate
B16: 2. Profit & Loss | C16: 5-Year P&L: Revenue → EBITDA → PAT
B17: 3. Cash Flow | C17: Operating, Investing & Free Cash Flow to Firm
B18: 4. NPV & IRR | C18: Net Present Value, IRR, MIRR, Payback Period
B19: 5. ROI Analysis | C19: Return on Investment vs 12% Hurdle Rate — Invest/Pass
B20: 6. Sensitivity | C20: NPV & ROI sensitivity to key assumption changes
B21: 7. Decision Summary | C21: One-page investment recommendation with all key metrics
B23: LIVE DECISION SUMMARY (updates automatically as you edit Assumptions)
B24: Metric | C24: Value | D24: Hurdle / Benchmark | E24: Status
B25: NPV (₹) | C25: ='NPV & IRR'!C32 -> #VALUE! | D25: > 0 | E25: ='NPV & IRR'!E32 -> #VALUE!
B26: IRR (%) | C26: ='NPV & IRR'!C33 -> N/A | D26: > 12% | E26: ='NPV & IRR'!E33 -> ✅ ABOVE HURDLE
B27: Simple ROI (%) | C27: ='ROI Analysis'!C12 -> N/A | D27: ≥ 12% | E27: ='ROI Analysis'!E12 -> ✅ PASS
B28: Annualised ROI (%) | C28: ='ROI Analysis'!C13 -> N/A | D28: ≥ 12% | E28: ='ROI Analysis'!E13 -> ✅ PASS
B29: Payback Period | C29: ='NPV & IRR'!C34 -> 0 | D29: < 5 Years | E29: ='NPV & IRR'!E34 -> ✅ WITHIN LIFE
B30: Disc. Payback | C30: ='NPV & IRR'!C35 -> 0 | D30: < Project Life | E30: ='NPV & IRR'!E35 -> ✅ WITHIN LIFE
B31: INVEST? | C31: =Decision!C5 -> #VALUE! | D31: Hurdle = 12% | E31: =Decision!C5 -> #VALUE!
B32: 📌 Start in the Assumptions sheet. All other sheets update automatically. Do NOT edit formula cells (black text).

Sheet Assumptions
B2: PROJECT ASSUMPTIONS
B3: All blue cells are inputs — modify freely | Do not edit black formula cells
B5: PROJECT INFORMATION
B6: Project Name | C6: New Expansion Project
B7: Analysis Date | C7: =TODAY() -> 46096
B8: Analyst | C8: Akshay K Kothari, CA
B10: INVESTMENT & HURDLE RATE
B11: Initial Investment (₹) | C11: 5000000 | D11: Total upfront capital deployed (Year 0)
B12: Additional Year 1 Capex (₹) | C12: 500000 | D12: Year 1 maintenance / setup capex
B13: Working Capital Required (₹) | C13: 300000 | D13: Net working capital outflow at start
B14: Residual / Terminal Value (₹) | C14: 1000000 | D14: Estimated salvage value at end of Year 5
B16: Hurdle Rate / WACC (%) | C16: 0.12 | D16: Minimum acceptable ROI (12% default)
B17: Project Life (Years) | C17: 5 | D17: Number of projection years
B19: REVENUE ASSUMPTIONS
B20: Year 1 Revenue (₹) | C20: 3000000 | D20: Base year revenue
B21: Revenue Growth Rate — Yr 2 | C21: 0.2 | D21: YoY growth rate Year 2
B22: Revenue Growth Rate — Yr 3 | C22: 0.18 | D22: YoY growth rate Year 3
B23: Revenue Growth Rate — Yr 4 | C23: 0.15 | D23: YoY growth rate Year 4
B24: Revenue Growth Rate — Yr 5 | C24: 0.12 | D24: YoY growth rate Year 5
B26: COST & MARGIN ASSUMPTIONS
B27: COGS as % of Revenue | C27: 0.45 | D27: Cost of Goods Sold margin
B28: Operating Expenses (₹/yr Yr1) | C28: 500000 | D28: Fixed OpEx in Year 1
B29: OpEx Growth Rate (annual) | C29: 0.05 | D29: Operating cost escalation
B30: Depreciation (₹/yr) | C30: 900000 | D30: Annual straight-line D&A on total capex
B31: Interest Expense (₹/yr) | C31: 200000 | D31: Annual debt servicing cost
B32: Tax Rate (%) | C32: 0.25 | D32: Effective corporate tax rate
B34: 📌 Yellow cells are key assumptions. The hurdle rate is set to 12% — change in C16 to test scenarios.

Sheet P&L
B2: PROFIT & LOSS STATEMENT
B3: 5-Year Projection | All formulas link to Assumptions sheet
B5: Line Item | C5: 2025 | D5: 2026 | E5: 2027 | F5: 2028 | G5: 2029 | H5: 5-Yr Total
B6: Revenue | C6: =Assumptions!C20 -> 3000000 | D6: =C6*(1+Assumptions!C21) -> 3600000 | E6: =D6*(1+Assumptions!C22) -> 4248000 | F6: =E6*(1+Assumptions!C23) -> 4885200 | G6: =F6*(1+Assumptions!C24) -> 5471424 | H6: =SUM(C6,D6,E6,F6,G6) -> 21204624
B7: Cost of Goods Sold (COGS) | C7: =C6*Assumptions!C27 -> 1350000 | D7: =D6*Assumptions!C27 -> 1620000 | E7: =E6*Assumptions!C27 -> 1911600 | F7: =F6*Assumptions!C27 -> 2198340 | G7: =G6*Assumptions!C27 -> 2462140.8 | H7: =SUM(C7,D7,E7,F7,G7) -> 9542080.8
B8: Gross Profit | C8: =C6-C7 -> 1650000 | D8: =D6-D7 -> 1980000 | E8: =E6-E7 -> 2336400 | F8: =F6-F7 -> 2686860 | G8: =G6-G7 -> 3009283.2 | H8: =SUM(C8,D8,E8,F8,G8) -> 11662543
B9: Gross Margin % | C9: =IF(C6=0,0,C8/C6) -> 0.55 | D9: =IF(D6=0,0,D8/D6) -> 0.55 | E9: =IF(E6=0,0,E8/E6) -> 0.55 | F9: =IF(F6=0,0,F8/F6) -> 0.55 | G9: =IF(G6=0,0,G8/G6) -> 0.55 | H9: =IF(H6=0,0,H8/H6) -> 0.55
B10: Operating Expenses (OpEx) | C10: =Assumptions!C28 -> 500000 | D10: =C10*(1+Assumptions!C29) -> 525000 | E10: =D10*(1+Assumptions!C29) -> 551250 | F10: =E10*(1+Assumptions!C29) -> 578812.5 | G10: =F10*(1+Assumptions!C29) -> 607753.12 | H10: =SUM(C10,D10,E10,F10,G10) -> 2762815.6
B11: EBITDA | C11: =C8-C10 -> 1150000 | D11: =D8-D10 -> 1455000 | E11: =E8-E10 -> 1785150 | F11: =F8-F10 -> 2108047.5 | G11: =G8-G10 -> 2401530.1 | H11: =SUM(C11,D11,E11,F11,G11) -> 8899727.6
B12: EBITDA Margin % | C12: =IF(C6=0,0,C11/C6) -> 0.38333333 | D12: =IF(D6=0,0,D11/D6) -> 0.40416667 | E12: =IF(E6=0,0,E11/E6) -> 0.42023305 | F12: =IF(F6=0,0,F11/F6) -> 0.43151713 | G12: =IF(G6=0,0,G11/G6) -> 0.43892231 | H12: =IF(H6=0,0,H11/H6) -> 0.41970693
B13: Depreciation & Amortisation | C13: =Assumptions!C30 -> 900000 | D13: =Assumptions!C30 -> 900000 | E13: =Assumptions!C30 -> 900000 | F13: =Assumptions!C30 -> 900000 | G13: =Assumptions!C30 -> 900000 | H13: =SUM(C13,D13,E13,F13,G13) -> 4500000
B14: EBIT | C14: =C11-C13 -> 250000 | D14: =D11-D13 -> 555000 | E14: =E11-E13 -> 885150 | F14: =F11-F13 -> 1208047.5 | G14: =G11-G13 -> 1501530.1 | H14: =SUM(C14,D14,E14,F14,G14) -> 4399727.6
B15: Interest Expense | C15: =Assumptions!C31 -> 200000 | D15: =Assumptions!C31 -> 200000 | E15: =Assumptions!C31 -> 200000 | F15: =Assumptions!C31 -> 200000 | G15: =Assumptions!C31 -> 200000 | H15: =SUM(C15,D15,E15,F15,G15) -> 1000000
B16: EBT (Profit Before Tax) | C16: =C14-C15 -> 50000 | D16: =D14-D15 -> 355000 | E16: =E14-E15 -> 685150 | F16: =F14-F15 -> 1008047.5 | G16: =G14-G15 -> 1301530.1 | H16: =SUM(C16,D16,E16,F16,G16) -> 3399727.6
B17: Tax | C17: =MAX(0,C16*Assumptions!C32) -> 12500 | D17: =MAX(0,D16*Assumptions!C32) -> 88750 | E17: =MAX(0,E16*Assumptions!C32) -> 171287.5 | F17: =MAX(0,F16*Assumptions!C32) -> 252011.88 | G17: =MAX(0,G16*Assumptions!C32) -> 325382.52 | H17: =SUM(C17,D17,E17,F17,G17) -> 849931.89
B18: PAT (Net Profit) | C18: =C16-C17 -> 37500 | D18: =D16-D17 -> 266250 | E18: =E16-E17 -> 513862.5 | F18: =F16-F17 -> 756035.62 | G18: =G16-G17 -> 976147.56 | H18: =SUM(C18,D18,E18,F18,G18) -> 2549795.7
B19: Net Profit Margin % | C19: =IF(C6=0,0,C18/C6) -> 0.0125 | D19: =IF(D6=0,0,D18/D6) -> 0.073958333 | E19: =IF(E6=0,0,E18/E6) -> 0.12096575 | F19: =IF(F6=0,0,F18/F6) -> 0.15476042 | G19: =IF(G6=0,0,G18/G6) -> 0.17840832 | H19: =IF(H6=0,0,H18/H6) -> 0.12024715

Sheet Cash Flow
B2: CASH FLOW STATEMENT
B3: Operating · Investing · Financing | Free Cash Flow to Firm (FCFF)
B5: Line Item | C5: Year 0 | D5: 2025 | E5: 2026 | F5: 2027 | G5: 2028 | H5: 2029 | I5: 5-Yr Total
B6: A. OPERATING CASH FLOW
B7: Net Profit (PAT) | C7: 0 | D7: ='P&L'!C18 -> 37500 | E7: ='P&L'!D18 -> 266250 | F7: ='P&L'!E18 -> 513862.5 | G7: ='P&L'!F18 -> 756035.62 | H7: ='P&L'!G18 -> 976147.56 | I7: =SUM(D7,E7,F7,G7,H7) -> 2549795.7
B8: Add: Depreciation & Amortisation | C8: 0 | D8: ='P&L'!C13 -> 900000 | E8: ='P&L'!D13 -> 900000 | F8: ='P&L'!E13 -> 900000 | G8: ='P&L'!F13 -> 900000 | H8: ='P&L'!G13 -> 900000 | I8: =SUM(D8,E8,F8,G8,H8) -> 4500000
B9: Changes in Working Capital | C9: -Assumptions!C13 | D9: 0 | E9: 0 | F9: 0 | G9: 0 | H9: 0 | I9: =SUM(D9,E9,F9,G9,H9) -> 0
B10: Operating Cash Flow (OCF) | C10: =C9 -> -Assumptions!C13 | D10: =D7+D8 -> 937500 | E10: =E7+E8 -> 1166250 | F10: =F7+F8 -> 1413862.5 | G10: =G7+G8 -> 1656035.6 | H10: =H7+H8 -> 1876147.6 | I10: =SUM(D10,E10,F10,G10,H10) -> 7049795.7
B12: B. INVESTING CASH FLOW
B13: Initial Investment (Year 0) | C13: =-Assumptions!C11 -> -5000000 | D13: 0 | E13: 0 | F13: 0 | G13: 0 | H13: 0 | I13: =SUM(D13,E13,F13,G13,H13) -> 0
B14: Additional Capex | C14: 0 | D14: =-Assumptions!C12 -> -500000 | E14: =0 -> 0 | F14: =0 -> 0 | G14: =0 -> 0 | H14: =0 -> 0 | I14: =SUM(D14,E14,F14,G14,H14) -> -500000
B15: Residual / Terminal Value | C15: 0 | D15: 0 | E15: 0 | F15: 0 | G15: 0 | H15: =+Assumptions!C14 -> 1000000 | I15: =SUM(D15,E15,F15,G15,H15) -> 1000000
B16: Investing Cash Flow (ICF) | C16: =C13+C14+C15 -> -5000000 | D16: =D13+D14+D15 -> -500000 | E16: =E13+E14+E15 -> 0 | F16: =F13+F14+F15 -> 0 | G16: =G13+G14+G15 -> 0 | H16: =H13+H14+H15 -> 1000000 | I16: =SUM(D16,E16,F16,G16,H16) -> 500000
B18: C. FREE CASH FLOW TO FIRM (FCFF)
B19: FCFF = OCF + ICF | C19: =C10+C16 -> #VALUE! | D19: =D10+D16 -> 437500 | E19: =E10+E16 -> 1166250 | F19: =F10+F16 -> 1413862.5 | G19: =G10+G16 -> 1656035.6 | H19: =H10+H16 -> 2876147.6 | I19: =SUM(D19,E19,F19,G19,H19) -> 7549795.7
B21: D. CUMULATIVE CASH FLOW
B22: Cumulative FCFF | C22: =C19 -> #VALUE! | D22: =C22+D19 -> #VALUE! | E22: =D22+E19 -> #VALUE! | F22: =E22+F19 -> #VALUE! | G22: =F22+G19 -> #VALUE! | H22: =G22+H19 -> #VALUE! | I22: =SUM(D22,E22,F22,G22,H22) -> #VALUE!

Sheet NPV & IRR
B2: NPV, IRR & PAYBACK ANALYSIS
B3: Discounted Cash Flow Model | Hurdle Rate = 12%
B5: FCFF SCHEDULE (from Cash Flow sheet)
B6: Year | C6: FCFF (₹) | D6: Discount Factor | E6: PV of FCFF (₹)
B7: Year 0 | C7: ='Cash Flow'!C19 -> #VALUE! | D7: =1 -> 1 | E7: =C7*D7 -> #VALUE!
B8: 2025 | C8: ='Cash Flow'!D19 -> 437500 | D8: =1/(1+Assumptions!C16)^1 -> 0.89285714 | E8: =C8*D8 -> 390625
B9: 2026 | C9: ='Cash Flow'!E19 -> 1166250 | D9: =1/(1+Assumptions!C16)^2 -> 0.79719388 | E9: =C9*D9 -> 929727.36
B10: 2027 | C10: ='Cash Flow'!F19 -> 1413862.5 | D10: =1/(1+Assumptions!C16)^3 -> 0.71178025 | E10: =C10*D10 -> 1006359.4
B11: 2028 | C11: ='Cash Flow'!G19 -> 1656035.6 | D11: =1/(1+Assumptions!C16)^4 -> 0.63551808 | E11: =C11*D11 -> 1052440.6
B12: 2029 | C12: ='Cash Flow'!H19 -> 2876147.6 | D12: =1/(1+Assumptions!C16)^5 -> 0.56742686 | E12: =C12*D12 -> 1632003.4
B14: INVESTMENT DECISION METRICS
B15: Net Present Value (NPV) | C15: =SUM(E7:E13) -> #VALUE! | D15: NPV > 0 → Accept | E15: =IF(C15>0,"✅ POSITIVE","❌ NEGATIVE") -> #VALUE!
B16: Internal Rate of Return (IRR) | C16: =IFERROR(IRR(C7:C13),"N/A") -> N/A | D16: > 12% Hurdle Rate | E16: =IFERROR(IF(C16>Assumptions!C16,"✅ ABOVE HURDLE","❌ BELOW HURDLE"),"N/A") -> ✅ ABOVE HURDLE
B17: Modified IRR (MIRR) | C17: =IFERROR(MIRR(C7:C13,Assumptions!C16,Assumptions!C16),"N/A") -> N/A | D17: > 12% (finance & reinvest rate) | E17: =IFERROR(IF(C17>Assumptions!C16,"✅ ABOVE HURDLE","❌ BELOW HURDLE"),"N/A") -> ✅ ABOVE HURDLE
B18: Simple Payback Period | D18: < 5 Years | E18: =IFERROR(IF(C18<Assumptions!C17,"✅ WITHIN LIFE","❌ EXCEEDS LIFE"),"Check CF") -> ✅ WITHIN LIFE
B19: Discounted Payback Period | D19: < Project Life | E19: =IFERROR(IF(C19<Assumptions!C17,"✅ WITHIN LIFE","❌ EXCEEDS LIFE"),"Check CF") -> ✅ WITHIN LIFE
B20: Profitability Index (PI) | C20: =IFERROR((C15+ABS('Cash Flow'!C13))/ABS('Cash Flow'!C13),"N/A") -> N/A | D20: > 1.0x → Accept | E20: =IFERROR(IF(C20>1,"✅ ABOVE 1.0x","❌ BELOW 1.0x"),"N/A") -> ✅ ABOVE 1.0x
C32: =C15 -> #VALUE! | E32: =E15 -> #VALUE!
C33: =C16 -> N/A | E33: =E16 -> ✅ ABOVE HURDLE
C34: =C18 -> 0 | E34: =E18 -> ✅ WITHIN LIFE
C35: =C19 -> 0 | E35: =E19 -> ✅ WITHIN LIFE

Sheet ROI Analysis
B2: ROI ANALYSIS vs 12% HURDLE RATE
B3: Should you invest? ROI, Cash-on-Cash, Multiple metrics
B5: TOTAL RETURN CALCULATION
B6: Total Revenue (5 Years) | C6: ='P&L'!H6 -> 21204624 | D6: Sum of 5-yr P&L revenue
B7: Total Operating Cash Flow (5 Yr) | C7: ='Cash Flow'!I10 -> 7049795.7 | D7: Sum of 5-yr OCF
B8: Total FCFF (5 Years) | C8: ='Cash Flow'!I19 -> 7549795.7 | D8: Sum of 5-yr Free Cash Flow
B9: Total Initial Investment | C9: =ABS('Cash Flow'!C13)+ABS('Cash Flow'!C9)+Assumptions!C12 -> #VALUE! | D9: Initial invest + WC + Year 1 Capex
B11: ROI METRICS VS 12% HURDLE RATE | E11: Decision vs 12% Hurdle
B12: Simple ROI (%) | C12: =IFERROR((C8-C9)/C9,"N/A") -> N/A | D12: Hurdle = 12% | E12: =IFERROR(IF(C12>=Assumptions!C16,"✅ PASS","❌ FAIL"),"N/A") -> ✅ PASS
B13: Annualised ROI (CAGR of returns) | C13: =IFERROR((1+C12)^(1/Assumptions!C17)-1,"N/A") -> N/A | D13: Hurdle = 12% | E13: =IFERROR(IF(C13>=Assumptions!C16,"✅ PASS","❌ FAIL"),"N/A") -> ✅ PASS
B14: Cash-on-Cash Return (COCR) | C14: =IFERROR(C7/C9,"N/A") -> N/A | D14: Hurdle = 12% | E14: =IFERROR(IF(C14>1,"✅ Cash Positive","❌ Cash Negative"),"N/A") -> ✅ Cash Positive
B15: Total Value Multiple (TVOM) | C15: =IFERROR((C8+C9)/C9,"N/A") -> N/A | D15: Hurdle = 12% | E15: =IFERROR(IF(C15>=1.5,"✅ Strong","⚠ Weak"),"N/A") -> ✅ Strong
B16: NPV (from NPV & IRR sheet) | C16: ='NPV & IRR'!C15 -> #VALUE! | D16: Hurdle = 12% | E16: ='NPV & IRR'!E15 -> #VALUE!
B17: IRR vs Hurdle Rate | C17: ='NPV & IRR'!C16 -> N/A | D17: Hurdle = 12% | E17: ='NPV & IRR'!E16 -> ✅ ABOVE HURDLE
B20: =IF(AND('NPV & IRR'!C15>0,'NPV & IRR'!C16>Assumptions!C16,C12>=Assumptions!C16),"✅ INVEST — Project clears all hurdles (NPV>0, IRR>12%, ROI>12%)","❌ DO NOT INVEST — Project does not meet all 12% hurdle criteria") -> #VALUE!

Sheet Sensitivity
B2: SENSITIVITY ANALYSIS
B3: NPV and ROI response to changes in Revenue Growth & Discount Rate
B5: TABLE 1 — NPV SENSITIVITY (₹) | Rows = Discount Rate | Columns = Yr-2 Revenue Growth
B6: Rate \ Growth → | C6: 10% | D6: 15% | E6: 20% | F6: 25% | G6: 30% | H6: 35%
B7: 8% | C7: =_xludf.LET(R1,Assumptions!C20,GR2,0.1,GR3,Assumptions!C22,GR4,Assumptions!C23,GR5,Assumptions!C24,cogs,Assumptions!C27,opex1,Assumptions!C28,opgr,Assumptions!C29,da,Assumptions!C30,intx,Assumptions!C31,tax,Assumptions!C32,dr,0.08,inv,Assumptions!C11+Assumptions!C13,tv,Assumptions!C14,REV2,R1*(1+GR2),REV3,REV2*(1+GR3),REV4,REV3*(1+GR4),REV5,REV4*(1+GR5),pat,_xludf.LAMBDA(rev,opex,(rev*(1-cogs)-opex-da-intx)*(1-tax)+da),OP1,Assumptions!C28,OP2,OP1*(1+opgr),OP3,OP2*(1+opgr),OP4,OP3*(1+opgr),OP5,OP4*(1+opgr),FCF1,pat(R1,OP1)-Assumptions!C12,FCF2,pat(REV2,OP2),FCF3,pat(REV3,OP3),FCF4,pat(REV4,OP4),FCF5,pat(REV5,OP5)+tv,-inv+FCF1/(1+dr)^1+FCF2/(1+dr)^2+FCF3/(1+dr)^3+FCF4/(1+dr)^4+FCF5/(1+dr)^5) -> #NAME? | D7: =_xludf.LET(R1,Assumptions!C20,GR2,0.15,GR3,Assumptions!C22,GR4,Assumptions!C23,GR5,Assumptions!C24,cogs,Assumptions!C27,opex1,Assumptions!C28,opgr,Assumptions!C29,da,Assumptions!C30,intx,Assumptions!C31,tax,Assumptions!C32,dr,0.08,inv,Assumptions!C11+Assumptions!C13,tv,Assumptions!C14,REV2,R1*(1+GR2),REV3,REV2*(1+GR3),REV4,REV3*(1+GR4),REV5,REV4*(1+GR5),pat,_xludf.LAMBDA(rev,opex,(rev*(1-cogs)-opex-da-intx)*(1-tax)+da),OP1,Assumptions!C28,OP2,OP1*(1+opgr),OP3,OP2*(1+opgr),OP4,OP3*(1+opgr),OP5,OP4*(1+opgr),FCF1,pat(R1,OP1)-Assumptions!C12,FCF2,pat(REV2,OP2),FCF3,pat(REV3,OP3),FCF4,pat(REV4,OP4),FCF5,pat(REV5,OP5)+tv,-inv+FCF1/(1+dr)^1+FCF2/(1+dr)^2+FCF3/(1+dr)^3+FCF4/(1+dr)^4+FCF5/(1+dr)^5) -> #NAME? | E7: =_xludf.LET(R1,Assumptions!C20,GR2,0.2,GR3,Assumptions!C22,GR4,Assumptions!C23,GR5,Assumptions!C24,cogs,Assumptions!C27,opex1,Assumptions!C28,opgr,Assumptions!C29,da,Assumptions!C30,intx,Assumptions!C31,tax,Assumptions!C32,dr,0.08,inv,Assumptions!C11+Assumptions!C13,tv,Assumptions!C14,REV2,R1*(1+GR2),REV3,REV2*(1+GR3),REV4,REV3*(1+GR4),REV5,REV4*(1+GR5),pat,_xludf.LAMBDA(rev,opex,(rev*(1-cogs)-opex-da-intx)*(1-tax)+da),OP1,Assumptions!C28,OP2,OP1*(1+opgr),OP3,OP2*(1+opgr),OP4,OP3*(1+opgr),OP5,OP4*(1+opgr),FCF1,pat(R1,OP1)-Assumptions!C12,FCF2,pat(REV2,OP2),FCF3,pat(REV3,OP3),FCF4,pat(REV4,OP4),FCF5,pat(REV5,OP5)+tv,-inv+FCF1/(1+dr)^1+FCF2/(1+dr)^2+FCF3/(1+dr)^3+FCF4/(1+dr)^4+FCF5/(1+dr)^5) -> #NAME? | F7: =_xludf.LET(R1,Assumptions!C20,GR2,0.25,GR3,Assumptions!C22,GR4,Assumptions!C23,GR5,Assumptions!C24,cogs,Assumptions!C27,opex1,Assumptions!C28,opgr,Assumptions!C29,da,Assumptions!C30,intx,Assumptions!C31,tax,Assumptions!C32,dr,0.08,inv,Assumptions!C11+Assumptions!C13,tv,Assumptions!C14,REV2,R1*(1+GR2),REV3,REV2*(1+GR3),REV4,REV3*(1+GR4),REV5,REV4*(1+GR5),pat,_xludf.LAMBDA(rev,opex,(rev*(1-cogs)-opex-da-intx)*(1-tax)+da),OP1,Assumptions!C28,OP2,OP1*(1+opgr),OP3,OP2*(1+opgr),OP4,OP3*(1+opgr),OP5,OP4*(1+opgr),FCF1,pat(R1,OP1)-Assumptions!C12,FCF2,pat(REV2,OP2),FCF3,pat(REV3,OP3),FCF4,pat(REV4,OP4),FCF5,pat(REV5,OP5)+tv,-inv+FCF1/(1+dr)^1+FCF2/(1+dr)^2+FCF3/(1+dr)^3+FCF4/(1+dr)^4+FCF5/(1+dr)^5) -> #NAME? | G7: =_xludf.LET(R1,Assumptions!C20,GR2,0.3,GR3,Assumptions!C22,GR4,Assumptions!C23,GR5,Assumptions!C24,cogs,Assumptions!C27,opex1,Assumptions!C28,opgr,Assumptions!C29,da,Assumptions!C30,intx,Assumptions!C31,tax,Assumptions!C32,dr,0.08,inv,Assumptions!C11+Assumptions!C13,tv,Assumptions!C14,REV2,R1*(1+GR2),REV3,REV2*(1+GR3),REV4,REV3*(1+GR4),REV5,REV4*(1+GR5),pat,_xludf.LAMBDA(rev,opex,(rev*(1-cogs)-opex-da-intx)*(1-tax)+da),OP1,Assumptions!C28,OP2,OP1*(1+opgr),OP3,OP2*(1+opgr),OP4,OP3*(1+opgr),OP5,OP4*(1+opgr),FCF1,pat(R1,OP1)-Assumptions!C12,FCF2,pat(REV2,OP2),FCF3,pat(REV3,OP3),FCF4,pat(REV4,OP4),FCF5,pat(REV5,OP5)+tv,-inv+FCF1/(1+dr)^1+FCF2/(1+dr)^2+FCF3/(1+dr)^3+FCF4/(1+dr)^4+FCF5/(1+dr)^5) -> #NAME? | H7: =_xludf.LET(R1,Assumptions!C20,GR2,0.35,GR3,Assumptions!C22,GR4,Assumptions!C23,GR5,Assumptions!C24,cogs,Assumptions!C27,opex1,Assumptions!C28,opgr,Assumptions!C29,da,Assumptions!C30,intx,Assumptions!C31,tax,Assumptions!C32,dr,0.08,inv,Assumptions!C11+Assumptions!C13,tv,Assumptions!C14,REV2,R1*(1+GR2),REV3,REV2*(1+GR3),REV4,REV3*(1+GR4),REV5,REV4*(1+GR5),pat,_xludf.LAMBDA(rev,opex,(rev*(1-cogs)-opex-da-intx)*(1-tax)+da),OP1,Assumptions!C28,OP2,OP1*(1+opgr),OP3,OP2*(1+opgr),OP4,OP3*(1+opgr),OP5,OP4*(1+opgr),FCF1,pat(R1,OP1)-Assumptions!C12,FCF2,pat(REV2,OP2),FCF3,pat(REV3,OP3),FCF4,pat(REV4,OP4),FCF5,pat(REV5,OP5)+tv,-inv+FCF1/(1+dr)^1+FCF2/(1+dr)^2+FCF3/(1+dr)^3+FCF4/(1+dr)^4+FCF5/(1+dr)^5) -> #NAME?
B8: 10% | C8: =_xludf.LET(R1,Assumptions!C20,GR2,0.1,GR3,Assumptions!C22,GR4,Assumptions!C23,GR5,Assumptions!C24,cogs,Assumptions!C27,opex1,Assumptions!C28,opgr,Assumptions!C29,da,Assumptions!C30,intx,Assumptions!C31,tax,Assumptions!C32,dr,0.1,inv,Assumptions!C11+Assumptions!C13,tv,Assumptions!C14,REV2,R1*(1+GR2),REV3,REV2*(1+GR3),REV4,REV3*(1+GR4),REV5,REV4*(1+GR5),pat,_xludf.LAMBDA(rev,opex,(rev*(1-cogs)-opex-da-intx)*(1-tax)+da),OP1,Assumptions!C28,OP2,OP1*(1+opgr),OP3,OP2*(1+opgr),OP4,OP3*(1+opgr),OP5,OP4*(1+opgr),FCF1,pat(R1,OP1)-Assumptions!C12,FCF2,pat(REV2,OP2),FCF3,pat(REV3,OP3),FCF4,pat(REV4,OP4),FCF5,pat(REV5,OP5)+tv,-inv+FCF1/(1+dr)^1+FCF2/(1+dr)^2+FCF3/(1+dr)^3+FCF4/(1+dr)^4+FCF5/(1+dr)^5) -> #NAME? | D8: =_xludf.LET(R1,Assumptions!C20,GR2,0.15,GR3,Assumptions!C22,GR4,Assumptions!C23,GR5,Assumptions!C24,cogs,Assumptions!C27,opex1,Assumptions!C28,opgr,Assumptions!C29,da,Assumptions!C30,intx,Assumptions!C31,tax,Assumptions!C32,dr,0.1,inv,Assumptions!C11+Assumptions!C13,tv,Assumptions!C14,REV2,R1*(1+GR2),REV3,REV2*(1+GR3),REV4,REV3*(1+GR4),REV5,REV4*(1+GR5),pat,_xludf.LAMBDA(rev,opex,(rev*(1-cogs)-opex-da-intx)*(1-tax)+da),OP1,Assumptions!C28,OP2,OP1*(1+opgr),OP3,OP2*(1+opgr),OP4,OP3*(1+opgr),OP5,OP4*(1+opgr),FCF1,pat(R1,OP1)-Assumptions!C12,FCF2,pat(REV2,OP2),FCF3,pat(REV3,OP3),FCF4,pat(REV4,OP4),FCF5,pat(REV5,OP5)+tv,-inv+FCF1/(1+dr)^1+FCF2/(1+dr)^2+FCF3/(1+dr)^3+FCF4/(1+dr)^4+FCF5/(1+dr)^5) -> #NAME? | E8: =_xludf.LET(R1,Assumptions!C20,GR2,0.2,GR3,Assumptions!C22,GR4,Assumptions!C23,GR5,Assumptions!C24,cogs,Assumptions!C27,opex1,Assumptions!C28,opgr,Assumptions!C29,da,Assumptions!C30,intx,Assumptions!C31,tax,Assumptions!C32,dr,0.1,inv,Assumptions!C11+Assumptions!C13,tv,Assumptions!C14,REV2,R1*(1+GR2),REV3,REV2*(1+GR3),REV4,REV3*(1+GR4),REV5,REV4*(1+GR5),pat,_xludf.LAMBDA(rev,opex,(rev*(1-cogs)-opex-da-intx)*(1-tax)+da),OP1,Assumptions!C28,OP2,OP1*(1+opgr),OP3,OP2*(1+opgr),OP4,OP3*(1+opgr),OP5,OP4*(1+opgr),FCF1,pat(R1,OP1)-Assumptions!C12,FCF2,pat(REV2,OP2),FCF3,pat(REV3,OP3),FCF4,pat(REV4,OP4),FCF5,pat(REV5,OP5)+tv,-inv+FCF1/(1+dr)^1+FCF2/(1+dr)^2+FCF3/(1+dr)^3+FCF4/(1+dr)^4+FCF5/(1+dr)^5) -> #NAME? | F8: =_xludf.LET(R1,Assumptions!C20,GR2,0.25,GR3,Assumptions!C22,GR4,Assumptions!C23,GR5,Assumptions!C24,cogs,Assumptions!C27,opex1,Assumptions!C28,opgr,Assumptions!C29,da,Assumptions!C30,intx,Assumptions!C31,tax,Assumptions!C32,dr,0.1,inv,Assumptions!C11+Assumptions!C13,tv,Assumptions!C14,REV2,R1*(1+GR2),REV3,REV2*(1+GR3),REV4,REV3*(1+GR4),REV5,REV4*(1+GR5),pat,_xludf.LAMBDA(rev,opex,(rev*(1-cogs)-opex-da-intx)*(1-tax)+da),OP1,Assumptions!C28,OP2,OP1*(1+opgr),OP3,OP2*(1+opgr),OP4,OP3*(1+opgr),OP5,OP4*(1+opgr),FCF1,pat(R1,OP1)-Assumptions!C12,FCF2,pat(REV2,OP2),FCF3,pat(REV3,OP3),FCF4,pat(REV4,OP4),FCF5,pat(REV5,OP5)+tv,-inv+FCF1/(1+dr)^1+FCF2/(1+dr)^2+FCF3/(1+dr)^3+FCF4/(1+dr)^4+FCF5/(1+dr)^5) -> #NAME? | G8: =_xludf.LET(R1,Assumptions!C20,GR2,0.3,GR3,Assumptions!C22,GR4,Assumptions!C23,GR5,Assumptions!C24,cogs,Assumptions!C27,opex1,Assumptions!C28,opgr,Assumptions!C29,da,Assumptions!C30,intx,Assumptions!C31,tax,Assumptions!C32,dr,0.1,inv,Assumptions!C11+Assumptions!C13,tv,Assumptions!C14,REV2,R1*(1+GR2),REV3,REV2*(1+GR3),REV4,REV3*(1+GR4),REV5,REV4*(1+GR5),pat,_xludf.LAMBDA(rev,opex,(rev*(1-cogs)-opex-da-intx)*(1-tax)+da),OP1,Assumptions!C28,OP2,OP1*(1+opgr),OP3,OP2*(1+opgr),OP4,OP3*(1+opgr),OP5,OP4*(1+opgr),FCF1,pat(R1,OP1)-Assumptions!C12,FCF2,pat(REV2,OP2),FCF3,pat(REV3,OP3),FCF4,pat(REV4,OP4),FCF5,pat(REV5,OP5)+tv,-inv+FCF1/(1+dr)^1+FCF2/(1+dr)^2+FCF3/(1+dr)^3+FCF4/(1+dr)^4+FCF5/(1+dr)^5) -> #NAME? | H8: =_xludf.LET(R1,Assumptions!C20,GR2,0.35,GR3,Assumptions!C22,GR4,Assumptions!C23,GR5,Assumptions!C24,cogs,Assumptions!C27,opex1,Assumptions!C28,opgr,Assumptions!C29,da,Assumptions!C30,intx,Assumptions!C31,tax,Assumptions!C32,dr,0.1,inv,Assumptions!C11+Assumptions!C13,tv,Assumptions!C14,REV2,R1*(1+GR2),REV3,REV2*(1+GR3),REV4,REV3*(1+GR4),REV5,REV4*(1+GR5),pat,_xludf.LAMBDA(rev,opex,(rev*(1-cogs)-opex-da-intx)*(1-tax)+da),OP1,Assumptions!C28,OP2,OP1*(1+opgr),OP3,OP2*(1+opgr),OP4,OP3*(1+opgr),OP5,OP4*(1+opgr),FCF1,pat(R1,OP1)-Assumptions!C12,FCF2,pat(REV2,OP2),FCF3,pat(REV3,OP3),FCF4,pat(REV4,OP4),FCF5,pat(REV5,OP5)+tv,-inv+FCF1/(1+dr)^1+FCF2/(1+dr)^2+FCF3/(1+dr)^3+FCF4/(1+dr)^4+FCF5/(1+dr)^5) -> #NAME?
B9: 12% | C9: =_xludf.LET(R1,Assumptions!C20,GR2,0.1,GR3,Assumptions!C22,GR4,Assumptions!C23,GR5,Assumptions!C24,cogs,Assumptions!C27,opex1,Assumptions!C28,opgr,Assumptions!C29,da,Assumptions!C30,intx,Assumptions!C31,tax,Assumptions!C32,dr,0.12,inv,Assumptions!C11+Assumptions!C13,tv,Assumptions!C14,REV2,R1*(1+GR2),REV3,REV2*(1+GR3),REV4,REV3*(1+GR4),REV5,REV4*(1+GR5),pat,_xludf.LAMBDA(rev,opex,(rev*(1-cogs)-opex-da-intx)*(1-tax)+da),OP1,Assumptions!C28,OP2,OP1*(1+opgr),OP3,OP2*(1+opgr),OP4,OP3*(1+opgr),OP5,OP4*(1+opgr),FCF1,pat(R1,OP1)-Assumptions!C12,FCF2,pat(REV2,OP2),FCF3,pat(REV3,OP3),FCF4,pat(REV4,OP4),FCF5,pat(REV5,OP5)+tv,-inv+FCF1/(1+dr)^1+FCF2/(1+dr)^2+FCF3/(1+dr)^3+FCF4/(1+dr)^4+FCF5/(1+dr)^5) -> #NAME? | D9: =_xludf.LET(R1,Assumptions!C20,GR2,0.15,GR3,Assumptions!C22,GR4,Assumptions!C23,GR5,Assumptions!C24,cogs,Assumptions!C27,opex1,Assumptions!C28,opgr,Assumptions!C29,da,Assumptions!C30,intx,Assumptions!C31,tax,Assumptions!C32,dr,0.12,inv,Assumptions!C11+Assumptions!C13,tv,Assumptions!C14,REV2,R1*(1+GR2),REV3,REV2*(1+GR3),REV4,REV3*(1+GR4),REV5,REV4*(1+GR5),pat,_xludf.LAMBDA(rev,opex,(rev*(1-cogs)-opex-da-intx)*(1-tax)+da),OP1,Assumptions!C28,OP2,OP1*(1+opgr),OP3,OP2*(1+opgr),OP4,OP3*(1+opgr),OP5,OP4*(1+opgr),FCF1,pat(R1,OP1)-Assumptions!C12,FCF2,pat(REV2,OP2),FCF3,pat(REV3,OP3),FCF4,pat(REV4,OP4),FCF5,pat(REV5,OP5)+tv,-inv+FCF1/(1+dr)^1+FCF2/(1+dr)^2+FCF3/(1+dr)^3+FCF4/(1+dr)^4+FCF5/(1+dr)^5) -> #NAME? | E9: =_xludf.LET(R1,Assumptions!C20,GR2,0.2,GR3,Assumptions!C22,GR4,Assumptions!C23,GR5,Assumptions!C24,cogs,Assumptions!C27,opex1,Assumptions!C28,opgr,Assumptions!C29,da,Assumptions!C30,intx,Assumptions!C31,tax,Assumptions!C32,dr,0.12,inv,Assumptions!C11+Assumptions!C13,tv,Assumptions!C14,REV2,R1*(1+GR2),REV3,REV2*(1+GR3),REV4,REV3*(1+GR4),REV5,REV4*(1+GR5),pat,_xludf.LAMBDA(rev,opex,(rev*(1-cogs)-opex-da-intx)*(1-tax)+da),OP1,Assumptions!C28,OP2,OP1*(1+opgr),OP3,OP2*(1+opgr),OP4,OP3*(1+opgr),OP5,OP4*(1+opgr),FCF1,pat(R1,OP1)-Assumptions!C12,FCF2,pat(REV2,OP2),FCF3,pat(REV3,OP3),FCF4,pat(REV4,OP4),FCF5,pat(REV5,OP5)+tv,-inv+FCF1/(1+dr)^1+FCF2/(1+dr)^2+FCF3/(1+dr)^3+FCF4/(1+dr)^4+FCF5/(1+dr)^5) -> #NAME? | F9: =_xludf.LET(R1,Assumptions!C20,GR2,0.25,GR3,Assumptions!C22,GR4,Assumptions!C23,GR5,Assumptions!C24,cogs,Assumptions!C27,opex1,Assumptions!C28,opgr,Assumptions!C29,da,Assumptions!C30,intx,Assumptions!C31,tax,Assumptions!C32,dr,0.12,inv,Assumptions!C11+Assumptions!C13,tv,Assumptions!C14,REV2,R1*(1+GR2),REV3,REV2*(1+GR3),REV4,REV3*(1+GR4),REV5,REV4*(1+GR5),pat,_xludf.LAMBDA(rev,opex,(rev*(1-cogs)-opex-da-intx)*(1-tax)+da),OP1,Assumptions!C28,OP2,OP1*(1+opgr),OP3,OP2*(1+opgr),OP4,OP3*(1+opgr),OP5,OP4*(1+opgr),FCF1,pat(R1,OP1)-Assumptions!C12,FCF2,pat(REV2,OP2),FCF3,pat(REV3,OP3),FCF4,pat(REV4,OP4),FCF5,pat(REV5,OP5)+tv,-inv+FCF1/(1+dr)^1+FCF2/(1+dr)^2+FCF3/(1+dr)^3+FCF4/(1+dr)^4+FCF5/(1+dr)^5) -> #NAME? | G9: =_xludf.LET(R1,Assumptions!C20,GR2,0.3,GR3,Assumptions!C22,GR4,Assumptions!C23,GR5,Assumptions!C24,cogs,Assumptions!C27,opex1,Assumptions!C28,opgr,Assumptions!C29,da,Assumptions!C30,intx,Assumptions!C31,tax,Assumptions!C32,dr,0.12,inv,Assumptions!C11+Assumptions!C13,tv,Assumptions!C14,REV2,R1*(1+GR2),REV3,REV2*(1+GR3),REV4,REV3*(1+GR4),REV5,REV4*(1+GR5),pat,_xludf.LAMBDA(rev,opex,(rev*(1-cogs)-opex-da-intx)*(1-tax)+da),OP1,Assumptions!C28,OP2,OP1*(1+opgr),OP3,OP2*(1+opgr),OP4,OP3*(1+opgr),OP5,OP4*(1+opgr),FCF1,pat(R1,OP1)-Assumptions!C12,FCF2,pat(REV2,OP2),FCF3,pat(REV3,OP3),FCF4,pat(REV4,OP4),FCF5,pat(REV5,OP5)+tv,-inv+FCF1/(1+dr)^1+FCF2/(1+dr)^2+FCF3/(1+dr)^3+FCF4/(1+dr)^4+FCF5/(1+dr)^5) -> #NAME? | H9: =_xludf.LET(R1,Assumptions!C20,GR2,0.35,GR3,Assumptions!C22,GR4,Assumptions!C23,GR5,Assumptions!C24,cogs,Assumptions!C27,opex1,Assumptions!C28,opgr,Assumptions!C29,da,Assumptions!C30,intx,Assumptions!C31,tax,Assumptions!C32,dr,0.12,inv,Assumptions!C11+Assumptions!C13,tv,Assumptions!C14,REV2,R1*(1+GR2),REV3,REV2*(1+GR3),REV4,REV3*(1+GR4),REV5,REV4*(1+GR5),pat,_xludf.LAMBDA(rev,opex,(rev*(1-cogs)-opex-da-intx)*(1-tax)+da),OP1,Assumptions!C28,OP2,OP1*(1+opgr),OP3,OP2*(1+opgr),OP4,OP3*(1+opgr),OP5,OP4*(1+opgr),FCF1,pat(R1,OP1)-Assumptions!C12,FCF2,pat(REV2,OP2),FCF3,pat(REV3,OP3),FCF4,pat(REV4,OP4),FCF5,pat(REV5,OP5)+tv,-inv+FCF1/(1+dr)^1+FCF2/(1+dr)^2+FCF3/(1+dr)^3+FCF4/(1+dr)^4+FCF5/(1+dr)^5) -> #NAME?
B10: 14% | C10: =_xludf.LET(R1,Assumptions!C20,GR2,0.1,GR3,Assumptions!C22,GR4,Assumptions!C23,GR5,Assumptions!C24,cogs,Assumptions!C27,opex1,Assumptions!C28,opgr,Assumptions!C29,da,Assumptions!C30,intx,Assumptions!C31,tax,Assumptions!C32,dr,0.14,inv,Assumptions!C11+Assumptions!C13,tv,Assumptions!C14,REV2,R1*(1+GR2),REV3,REV2*(1+GR3),REV4,REV3*(1+GR4),REV5,REV4*(1+GR5),pat,_xludf.LAMBDA(rev,opex,(rev*(1-cogs)-opex-da-intx)*(1-tax)+da),OP1,Assumptions!C28,OP2,OP1*(1+opgr),OP3,OP2*(1+opgr),OP4,OP3*(1+opgr),OP5,OP4*(1+opgr),FCF1,pat(R1,OP1)-Assumptions!C12,FCF2,pat(REV2,OP2),FCF3,pat(REV3,OP3),FCF4,pat(REV4,OP4),FCF5,pat(REV5,OP5)+tv,-inv+FCF1/(1+dr)^1+FCF2/(1+dr)^2+FCF3/(1+dr)^3+FCF4/(1+dr)^4+FCF5/(1+dr)^5) -> #NAME? | D10: =_xludf.LET(R1,Assumptions!C20,GR2,0.15,GR3,Assumptions!C22,GR4,Assumptions!C23,GR5,Assumptions!C24,cogs,Assumptions!C27,opex1,Assumptions!C28,opgr,Assumptions!C29,da,Assumptions!C30,intx,Assumptions!C31,tax,Assumptions!C32,dr,0.14,inv,Assumptions!C11+Assumptions!C13,tv,Assumptions!C14,REV2,R1*(1+GR2),REV3,REV2*(1+GR3),REV4,REV3*(1+GR4),REV5,REV4*(1+GR5),pat,_xludf.LAMBDA(rev,opex,(rev*(1-cogs)-opex-da-intx)*(1-tax)+da),OP1,Assumptions!C28,OP2,OP1*(1+opgr),OP3,OP2*(1+opgr),OP4,OP3*(1+opgr),OP5,OP4*(1+opgr),FCF1,pat(R1,OP1)-Assumptions!C12,FCF2,pat(REV2,OP2),FCF3,pat(REV3,OP3),FCF4,pat(REV4,OP4),FCF5,pat(REV5,OP5)+tv,-inv+FCF1/(1+dr)^1+FCF2/(1+dr)^2+FCF3/(1+dr)^3+FCF4/(1+dr)^4+FCF5/(1+dr)^5) -> #NAME? | E10: =_xludf.LET(R1,Assumptions!C20,GR2,0.2,GR3,Assumptions!C22,GR4,Assumptions!C23,GR5,Assumptions!C24,cogs,Assumptions!C27,opex1,Assumptions!C28,opgr,Assumptions!C29,da,Assumptions!C30,intx,Assumptions!C31,tax,Assumptions!C32,dr,0.14,inv,Assumptions!C11+Assumptions!C13,tv,Assumptions!C14,REV2,R1*(1+GR2),REV3,REV2*(1+GR3),REV4,REV3*(1+GR4),REV5,REV4*(1+GR5),pat,_xludf.LAMBDA(rev,opex,(rev*(1-cogs)-opex-da-intx)*(1-tax)+da),OP1,Assumptions!C28,OP2,OP1*(1+opgr),OP3,OP2*(1+opgr),OP4,OP3*(1+opgr),OP5,OP4*(1+opgr),FCF1,pat(R1,OP1)-Assumptions!C12,FCF2,pat(REV2,OP2),FCF3,pat(REV3,OP3),FCF4,pat(REV4,OP4),FCF5,pat(REV5,OP5)+tv,-inv+FCF1/(1+dr)^1+FCF2/(1+dr)^2+FCF3/(1+dr)^3+FCF4/(1+dr)^4+FCF5/(1+dr)^5) -> #NAME? | F10: =_xludf.LET(R1,Assumptions!C20,GR2,0.25,GR3,Assumptions!C22,GR4,Assumptions!C23,GR5,Assumptions!C24,cogs,Assumptions!C27,opex1,Assumptions!C28,opgr,Assumptions!C29,da,Assumptions!C30,intx,Assumptions!C31,tax,Assumptions!C32,dr,0.14,inv,Assumptions!C11+Assumptions!C13,tv,Assumptions!C14,REV2,R1*(1+GR2),REV3,REV2*(1+GR3),REV4,REV3*(1+GR4),REV5,REV4*(1+GR5),pat,_xludf.LAMBDA(rev,opex,(rev*(1-cogs)-opex-da-intx)*(1-tax)+da),OP1,Assumptions!C28,OP2,OP1*(1+opgr),OP3,OP2*(1+opgr),OP4,OP3*(1+opgr),OP5,OP4*(1+opgr),FCF1,pat(R1,OP1)-Assumptions!C12,FCF2,pat(REV2,OP2),FCF3,pat(REV3,OP3),FCF4,pat(REV4,OP4),FCF5,pat(REV5,OP5)+tv,-inv+FCF1/(1+dr)^1+FCF2/(1+dr)^2+FCF3/(1+dr)^3+FCF4/(1+dr)^4+FCF5/(1+dr)^5) -> #NAME? | G10: =_xludf.LET(R1,Assumptions!C20,GR2,0.3,GR3,Assumptions!C22,GR4,Assumptions!C23,GR5,Assumptions!C24,cogs,Assumptions!C27,opex1,Assumptions!C28,opgr,Assumptions!C29,da,Assumptions!C30,intx,Assumptions!C31,tax,Assumptions!C32,dr,0.14,inv,Assumptions!C11+Assumptions!C13,tv,Assumptions!C14,REV2,R1*(1+GR2),REV3,REV2*(1+GR3),REV4,REV3*(1+GR4),REV5,REV4*(1+GR5),pat,_xludf.LAMBDA(rev,opex,(rev*(1-cogs)-opex-da-intx)*(1-tax)+da),OP1,Assumptions!C28,OP2,OP1*(1+opgr),OP3,OP2*(1+opgr),OP4,OP3*(1+opgr),OP5,OP4*(1+opgr),FCF1,pat(R1,OP1)-Assumptions!C12,FCF2,pat(REV2,OP2),FCF3,pat(REV3,OP3),FCF4,pat(REV4,OP4),FCF5,pat(REV5,OP5)+tv,-inv+FCF1/(1+dr)^1+FCF2/(1+dr)^2+FCF3/(1+dr)^3+FCF4/(1+dr)^4+FCF5/(1+dr)^5) -> #NAME? | H10: =_xludf.LET(R1,Assumptions!C20,GR2,0.35,GR3,Assumptions!C22,GR4,Assumptions!C23,GR5,Assumptions!C24,cogs,Assumptions!C27,opex1,Assumptions!C28,opgr,Assumptions!C29,da,Assumptions!C30,intx,Assumptions!C31,tax,Assumptions!C32,dr,0.14,inv,Assumptions!C11+Assumptions!C13,tv,Assumptions!C14,REV2,R1*(1+GR2),REV3,REV2*(1+GR3),REV4,REV3*(1+GR4),REV5,REV4*(1+GR5),pat,_xludf.LAMBDA(rev,opex,(rev*(1-cogs)-opex-da-intx)*(1-tax)+da),OP1,Assumptions!C28,OP2,OP1*(1+opgr),OP3,OP2*(1+opgr),OP4,OP3*(1+opgr),OP5,OP4*(1+opgr),FCF1,pat(R1,OP1)-Assumptions!C12,FCF2,pat(REV2,OP2),FCF3,pat(REV3,OP3),FCF4,pat(REV4,OP4),FCF5,pat(REV5,OP5)+tv,-inv+FCF1/(1+dr)^1+FCF2/(1+dr)^2+FCF3/(1+dr)^3+FCF4/(1+dr)^4+FCF5/(1+dr)^5) -> #NAME?
B11: 16% | C11: =_xludf.LET(R1,Assumptions!C20,GR2,0.1,GR3,Assumptions!C22,GR4,Assumptions!C23,GR5,Assumptions!C24,cogs,Assumptions!C27,opex1,Assumptions!C28,opgr,Assumptions!C29,da,Assumptions!C30,intx,Assumptions!C31,tax,Assumptions!C32,dr,0.16,inv,Assumptions!C11+Assumptions!C13,tv,Assumptions!C14,REV2,R1*(1+GR2),REV3,REV2*(1+GR3),REV4,REV3*(1+GR4),REV5,REV4*(1+GR5),pat,_xludf.LAMBDA(rev,opex,(rev*(1-cogs)-opex-da-intx)*(1-tax)+da),OP1,Assumptions!C28,OP2,OP1*(1+opgr),OP3,OP2*(1+opgr),OP4,OP3*(1+opgr),OP5,OP4*(1+opgr),FCF1,pat(R1,OP1)-Assumptions!C12,FCF2,pat(REV2,OP2),FCF3,pat(REV3,OP3),FCF4,pat(REV4,OP4),FCF5,pat(REV5,OP5)+tv,-inv+FCF1/(1+dr)^1+FCF2/(1+dr)^2+FCF3/(1+dr)^3+FCF4/(1+dr)^4+FCF5/(1+dr)^5) -> #NAME? | D11: =_xludf.LET(R1,Assumptions!C20,GR2,0.15,GR3,Assumptions!C22,GR4,Assumptions!C23,GR5,Assumptions!C24,cogs,Assumptions!C27,opex1,Assumptions!C28,opgr,Assumptions!C29,da,Assumptions!C30,intx,Assumptions!C31,tax,Assumptions!C32,dr,0.16,inv,Assumptions!C11+Assumptions!C13,tv,Assumptions!C14,REV2,R1*(1+GR2),REV3,REV2*(1+GR3),REV4,REV3*(1+GR4),REV5,REV4*(1+GR5),pat,_xludf.LAMBDA(rev,opex,(rev*(1-cogs)-opex-da-intx)*(1-tax)+da),OP1,Assumptions!C28,OP2,OP1*(1+opgr),OP3,OP2*(1+opgr),OP4,OP3*(1+opgr),OP5,OP4*(1+opgr),FCF1,pat(R1,OP1)-Assumptions!C12,FCF2,pat(REV2,OP2),FCF3,pat(REV3,OP3),FCF4,pat(REV4,OP4),FCF5,pat(REV5,OP5)+tv,-inv+FCF1/(1+dr)^1+FCF2/(1+dr)^2+FCF3/(1+dr)^3+FCF4/(1+dr)^4+FCF5/(1+dr)^5) -> #NAME? | E11: =_xludf.LET(R1,Assumptions!C20,GR2,0.2,GR3,Assumptions!C22,GR4,Assumptions!C23,GR5,Assumptions!C24,cogs,Assumptions!C27,opex1,Assumptions!C28,opgr,Assumptions!C29,da,Assumptions!C30,intx,Assumptions!C31,tax,Assumptions!C32,dr,0.16,inv,Assumptions!C11+Assumptions!C13,tv,Assumptions!C14,REV2,R1*(1+GR2),REV3,REV2*(1+GR3),REV4,REV3*(1+GR4),REV5,REV4*(1+GR5),pat,_xludf.LAMBDA(rev,opex,(rev*(1-cogs)-opex-da-intx)*(1-tax)+da),OP1,Assumptions!C28,OP2,OP1*(1+opgr),OP3,OP2*(1+opgr),OP4,OP3*(1+opgr),OP5,OP4*(1+opgr),FCF1,pat(R1,OP1)-Assumptions!C12,FCF2,pat(REV2,OP2),FCF3,pat(REV3,OP3),FCF4,pat(REV4,OP4),FCF5,pat(REV5,OP5)+tv,-inv+FCF1/(1+dr)^1+FCF2/(1+dr)^2+FCF3/(1+dr)^3+FCF4/(1+dr)^4+FCF5/(1+dr)^5) -> #NAME? | F11: =_xludf.LET(R1,Assumptions!C20,GR2,0.25,GR3,Assumptions!C22,GR4,Assumptions!C23,GR5,Assumptions!C24,cogs,Assumptions!C27,opex1,Assumptions!C28,opgr,Assumptions!C29,da,Assumptions!C30,intx,Assumptions!C31,tax,Assumptions!C32,dr,0.16,inv,Assumptions!C11+Assumptions!C13,tv,Assumptions!C14,REV2,R1*(1+GR2),REV3,REV2*(1+GR3),REV4,REV3*(1+GR4),REV5,REV4*(1+GR5),pat,_xludf.LAMBDA(rev,opex,(rev*(1-cogs)-opex-da-intx)*(1-tax)+da),OP1,Assumptions!C28,OP2,OP1*(1+opgr),OP3,OP2*(1+opgr),OP4,OP3*(1+opgr),OP5,OP4*(1+opgr),FCF1,pat(R1,OP1)-Assumptions!C12,FCF2,pat(REV2,OP2),FCF3,pat(REV3,OP3),FCF4,pat(REV4,OP4),FCF5,pat(REV5,OP5)+tv,-inv+FCF1/(1+dr)^1+FCF2/(1+dr)^2+FCF3/(1+dr)^3+FCF4/(1+dr)^4+FCF5/(1+dr)^5) -> #NAME? | G11: =_xludf.LET(R1,Assumptions!C20,GR2,0.3,GR3,Assumptions!C22,GR4,Assumptions!C23,GR5,Assumptions!C24,cogs,Assumptions!C27,opex1,Assumptions!C28,opgr,Assumptions!C29,da,Assumptions!C30,intx,Assumptions!C31,tax,Assumptions!C32,dr,0.16,inv,Assumptions!C11+Assumptions!C13,tv,Assumptions!C14,REV2,R1*(1+GR2),REV3,REV2*(1+GR3),REV4,REV3*(1+GR4),REV5,REV4*(1+GR5),pat,_xludf.LAMBDA(rev,opex,(rev*(1-cogs)-opex-da-intx)*(1-tax)+da),OP1,Assumptions!C28,OP2,OP1*(1+opgr),OP3,OP2*(1+opgr),OP4,OP3*(1+opgr),OP5,OP4*(1+opgr),FCF1,pat(R1,OP1)-Assumptions!C12,FCF2,pat(REV2,OP2),FCF3,pat(REV3,OP3),FCF4,pat(REV4,OP4),FCF5,pat(REV5,OP5)+tv,-inv+FCF1/(1+dr)^1+FCF2/(1+dr)^2+FCF3/(1+dr)^3+FCF4/(1+dr)^4+FCF5/(1+dr)^5) -> #NAME? | H11: =_xludf.LET(R1,Assumptions!C20,GR2,0.35,GR3,Assumptions!C22,GR4,Assumptions!C23,GR5,Assumptions!C24,cogs,Assumptions!C27,opex1,Assumptions!C28,opgr,Assumptions!C29,da,Assumptions!C30,intx,Assumptions!C31,tax,Assumptions!C32,dr,0.16,inv,Assumptions!C11+Assumptions!C13,tv,Assumptions!C14,REV2,R1*(1+GR2),REV3,REV2*(1+GR3),REV4,REV3*(1+GR4),REV5,REV4*(1+GR5),pat,_xludf.LAMBDA(rev,opex,(rev*(1-cogs)-opex-da-intx)*(1-tax)+da),OP1,Assumptions!C28,OP2,OP1*(1+opgr),OP3,OP2*(1+opgr),OP4,OP3*(1+opgr),OP5,OP4*(1+opgr),FCF1,pat(R1,OP1)-Assumptions!C12,FCF2,pat(REV2,OP2),FCF3,pat(REV3,OP3),FCF4,pat(REV4,OP4),FCF5,pat(REV5,OP5)+tv,-inv+FCF1/(1+dr)^1+FCF2/(1+dr)^2+FCF3/(1+dr)^3+FCF4/(1+dr)^4+FCF5/(1+dr)^5) -> #NAME?
B12: 18% | C12: =_xludf.LET(R1,Assumptions!C20,GR2,0.1,GR3,Assumptions!C22,GR4,Assumptions!C23,GR5,Assumptions!C24,cogs,Assumptions!C27,opex1,Assumptions!C28,opgr,Assumptions!C29,da,Assumptions!C30,intx,Assumptions!C31,tax,Assumptions!C32,dr,0.18,inv,Assumptions!C11+Assumptions!C13,tv,Assumptions!C14,REV2,R1*(1+GR2),REV3,REV2*(1+GR3),REV4,REV3*(1+GR4),REV5,REV4*(1+GR5),pat,_xludf.LAMBDA(rev,opex,(rev*(1-cogs)-opex-da-intx)*(1-tax)+da),OP1,Assumptions!C28,OP2,OP1*(1+opgr),OP3,OP2*(1+opgr),OP4,OP3*(1+opgr),OP5,OP4*(1+opgr),FCF1,pat(R1,OP1)-Assumptions!C12,FCF2,pat(REV2,OP2),FCF3,pat(REV3,OP3),FCF4,pat(REV4,OP4),FCF5,pat(REV5,OP5)+tv,-inv+FCF1/(1+dr)^1+FCF2/(1+dr)^2+FCF3/(1+dr)^3+FCF4/(1+dr)^4+FCF5/(1+dr)^5) -> #NAME? | D12: =_xludf.LET(R1,Assumptions!C20,GR2,0.15,GR3,Assumptions!C22,GR4,Assumptions!C23,GR5,Assumptions!C24,cogs,Assumptions!C27,opex1,Assumptions!C28,opgr,Assumptions!C29,da,Assumptions!C30,intx,Assumptions!C31,tax,Assumptions!C32,dr,0.18,inv,Assumptions!C11+Assumptions!C13,tv,Assumptions!C14,REV2,R1*(1+GR2),REV3,REV2*(1+GR3),REV4,REV3*(1+GR4),REV5,REV4*(1+GR5),pat,_xludf.LAMBDA(rev,opex,(rev*(1-cogs)-opex-da-intx)*(1-tax)+da),OP1,Assumptions!C28,OP2,OP1*(1+opgr),OP3,OP2*(1+opgr),OP4,OP3*(1+opgr),OP5,OP4*(1+opgr),FCF1,pat(R1,OP1)-Assumptions!C12,FCF2,pat(REV2,OP2),FCF3,pat(REV3,OP3),FCF4,pat(REV4,OP4),FCF5,pat(REV5,OP5)+tv,-inv+FCF1/(1+dr)^1+FCF2/(1+dr)^2+FCF3/(1+dr)^3+FCF4/(1+dr)^4+FCF5/(1+dr)^5) -> #NAME? | E12: =_xludf.LET(R1,Assumptions!C20,GR2,0.2,GR3,Assumptions!C22,GR4,Assumptions!C23,GR5,Assumptions!C24,cogs,Assumptions!C27,opex1,Assumptions!C28,opgr,Assumptions!C29,da,Assumptions!C30,intx,Assumptions!C31,tax,Assumptions!C32,dr,0.18,inv,Assumptions!C11+Assumptions!C13,tv,Assumptions!C14,REV2,R1*(1+GR2),REV3,REV2*(1+GR3),REV4,REV3*(1+GR4),REV5,REV4*(1+GR5),pat,_xludf.LAMBDA(rev,opex,(rev*(1-cogs)-opex-da-intx)*(1-tax)+da),OP1,Assumptions!C28,OP2,OP1*(1+opgr),OP3,OP2*(1+opgr),OP4,OP3*(1+opgr),OP5,OP4*(1+opgr),FCF1,pat(R1,OP1)-Assumptions!C12,FCF2,pat(REV2,OP2),FCF3,pat(REV3,OP3),FCF4,pat(REV4,OP4),FCF5,pat(REV5,OP5)+tv,-inv+FCF1/(1+dr)^1+FCF2/(1+dr)^2+FCF3/(1+dr)^3+FCF4/(1+dr)^4+FCF5/(1+dr)^5) -> #NAME? | F12: =_xludf.LET(R1,Assumptions!C20,GR2,0.25,GR3,Assumptions!C22,GR4,Assumptions!C23,GR5,Assumptions!C24,cogs,Assumptions!C27,opex1,Assumptions!C28,opgr,Assumptions!C29,da,Assumptions!C30,intx,Assumptions!C31,tax,Assumptions!C32,dr,0.18,inv,Assumptions!C11+Assumptions!C13,tv,Assumptions!C14,REV2,R1*(1+GR2),REV3,REV2*(1+GR3),REV4,REV3*(1+GR4),REV5,REV4*(1+GR5),pat,_xludf.LAMBDA(rev,opex,(rev*(1-cogs)-opex-da-intx)*(1-tax)+da),OP1,Assumptions!C28,OP2,OP1*(1+opgr),OP3,OP2*(1+opgr),OP4,OP3*(1+opgr),OP5,OP4*(1+opgr),FCF1,pat(R1,OP1)-Assumptions!C12,FCF2,pat(REV2,OP2),FCF3,pat(REV3,OP3),FCF4,pat(REV4,OP4),FCF5,pat(REV5,OP5)+tv,-inv+FCF1/(1+dr)^1+FCF2/(1+dr)^2+FCF3/(1+dr)^3+FCF4/(1+dr)^4+FCF5/(1+dr)^5) -> #NAME? | G12: =_xludf.LET(R1,Assumptions!C20,GR2,0.3,GR3,Assumptions!C22,GR4,Assumptions!C23,GR5,Assumptions!C24,cogs,Assumptions!C27,opex1,Assumptions!C28,opgr,Assumptions!C29,da,Assumptions!C30,intx,Assumptions!C31,tax,Assumptions!C32,dr,0.18,inv,Assumptions!C11+Assumptions!C13,tv,Assumptions!C14,REV2,R1*(1+GR2),REV3,REV2*(1+GR3),REV4,REV3*(1+GR4),REV5,REV4*(1+GR5),pat,_xludf.LAMBDA(rev,opex,(rev*(1-cogs)-opex-da-intx)*(1-tax)+da),OP1,Assumptions!C28,OP2,OP1*(1+opgr),OP3,OP2*(1+opgr),OP4,OP3*(1+opgr),OP5,OP4*(1+opgr),FCF1,pat(R1,OP1)-Assumptions!C12,FCF2,pat(REV2,OP2),FCF3,pat(REV3,OP3),FCF4,pat(REV4,OP4),FCF5,pat(REV5,OP5)+tv,-inv+FCF1/(1+dr)^1+FCF2/(1+dr)^2+FCF3/(1+dr)^3+FCF4/(1+dr)^4+FCF5/(1+dr)^5) -> #NAME? | H12: =_xludf.LET(R1,Assumptions!C20,GR2,0.35,GR3,Assumptions!C22,GR4,Assumptions!C23,GR5,Assumptions!C24,cogs,Assumptions!C27,opex1,Assumptions!C28,opgr,Assumptions!C29,da,Assumptions!C30,intx,Assumptions!C31,tax,Assumptions!C32,dr,0.18,inv,Assumptions!C11+Assumptions!C13,tv,Assumptions!C14,REV2,R1*(1+GR2),REV3,REV2*(1+GR3),REV4,REV3*(1+GR4),REV5,REV4*(1+GR5),pat,_xludf.LAMBDA(rev,opex,(rev*(1-cogs)-opex-da-intx)*(1-tax)+da),OP1,Assumptions!C28,OP2,OP1*(1+opgr),OP3,OP2*(1+opgr),OP4,OP3*(1+opgr),OP5,OP4*(1+opgr),FCF1,pat(R1,OP1)-Assumptions!C12,FCF2,pat(REV2,OP2),FCF3,pat(REV3,OP3),FCF4,pat(REV4,OP4),FCF5,pat(REV5,OP5)+tv,-inv+FCF1/(1+dr)^1+FCF2/(1+dr)^2+FCF3/(1+dr)^3+FCF4/(1+dr)^4+FCF5/(1+dr)^5) -> #NAME?
B13: ⬆ Highlighted row = Base case (12% hurdle rate). Green = NPV positive (invest). Red = NPV negative (reject).
B15: TABLE 2 — SIMPLE ROI (%) SENSITIVITY | Rows = Year 1 Revenue | Columns = Yr-2 Growth
B16: Rev1 \ Growth → | C16: 10% | D16: 15% | E16: 20% | F16: 25% | G16: 30% | H16: 35%
B17: ₹20L | C17: =_xludf.LET(R1,2000000,GR2,0.1,GR3,Assumptions!C22,GR4,Assumptions!C23,GR5,Assumptions!C24,cogs,Assumptions!C27,opex1,Assumptions!C28,opgr,Assumptions!C29,da,Assumptions!C30,intx,Assumptions!C31,tax,Assumptions!C32,inv,Assumptions!C11+Assumptions!C13+Assumptions!C12,tv,Assumptions!C14,REV2,R1*(1+GR2),REV3,REV2*(1+GR3),REV4,REV3*(1+GR4),REV5,REV4*(1+GR5),OP1,Assumptions!C28,OP2,OP1*(1+opgr),OP3,OP2*(1+opgr),OP4,OP3*(1+opgr),OP5,OP4*(1+opgr),pat,_xludf.LAMBDA(rev,opex,(rev*(1-cogs)-opex-da-intx)*(1-tax)+da),fcf_total,pat(R1,OP1)+pat(REV2,OP2)+pat(REV3,OP3)+pat(REV4,OP4)+pat(REV5,OP5)+tv,(fcf_total-inv)/inv) -> #NAME? | D17: =_xludf.LET(R1,2000000,GR2,0.15,GR3,Assumptions!C22,GR4,Assumptions!C23,GR5,Assumptions!C24,cogs,Assumptions!C27,opex1,Assumptions!C28,opgr,Assumptions!C29,da,Assumptions!C30,intx,Assumptions!C31,tax,Assumptions!C32,inv,Assumptions!C11+Assumptions!C13+Assumptions!C12,tv,Assumptions!C14,REV2,R1*(1+GR2),REV3,REV2*(1+GR3),REV4,REV3*(1+GR4),REV5,REV4*(1+GR5),OP1,Assumptions!C28,OP2,OP1*(1+opgr),OP3,OP2*(1+opgr),OP4,OP3*(1+opgr),OP5,OP4*(1+opgr),pat,_xludf.LAMBDA(rev,opex,(rev*(1-cogs)-opex-da-intx)*(1-tax)+da),fcf_total,pat(R1,OP1)+pat(REV2,OP2)+pat(REV3,OP3)+pat(REV4,OP4)+pat(REV5,OP5)+tv,(fcf_total-inv)/inv) -> #NAME? | E17: =_xludf.LET(R1,2000000,GR2,0.2,GR3,Assumptions!C22,GR4,Assumptions!C23,GR5,Assumptions!C24,cogs,Assumptions!C27,opex1,Assumptions!C28,opgr,Assumptions!C29,da,Assumptions!C30,intx,Assumptions!C31,tax,Assumptions!C32,inv,Assumptions!C11+Assumptions!C13+Assumptions!C12,tv,Assumptions!C14,REV2,R1*(1+GR2),REV3,REV2*(1+GR3),REV4,REV3*(1+GR4),REV5,REV4*(1+GR5),OP1,Assumptions!C28,OP2,OP1*(1+opgr),OP3,OP2*(1+opgr),OP4,OP3*(1+opgr),OP5,OP4*(1+opgr),pat,_xludf.LAMBDA(rev,opex,(rev*(1-cogs)-opex-da-intx)*(1-tax)+da),fcf_total,pat(R1,OP1)+pat(REV2,OP2)+pat(REV3,OP3)+pat(REV4,OP4)+pat(REV5,OP5)+tv,(fcf_total-inv)/inv) -> #NAME? | F17: =_xludf.LET(R1,2000000,GR2,0.25,GR3,Assumptions!C22,GR4,Assumptions!C23,GR5,Assumptions!C24,cogs,Assumptions!C27,opex1,Assumptions!C28,opgr,Assumptions!C29,da,Assumptions!C30,intx,Assumptions!C31,tax,Assumptions!C32,inv,Assumptions!C11+Assumptions!C13+Assumptions!C12,tv,Assumptions!C14,REV2,R1*(1+GR2),REV3,REV2*(1+GR3),REV4,REV3*(1+GR4),REV5,REV4*(1+GR5),OP1,Assumptions!C28,OP2,OP1*(1+opgr),OP3,OP2*(1+opgr),OP4,OP3*(1+opgr),OP5,OP4*(1+opgr),pat,_xludf.LAMBDA(rev,opex,(rev*(1-cogs)-opex-da-intx)*(1-tax)+da),fcf_total,pat(R1,OP1)+pat(REV2,OP2)+pat(REV3,OP3)+pat(REV4,OP4)+pat(REV5,OP5)+tv,(fcf_total-inv)/inv) -> #NAME? | G17: =_xludf.LET(R1,2000000,GR2,0.3,GR3,Assumptions!C22,GR4,Assumptions!C23,GR5,Assumptions!C24,cogs,Assumptions!C27,opex1,Assumptions!C28,opgr,Assumptions!C29,da,Assumptions!C30,intx,Assumptions!C31,tax,Assumptions!C32,inv,Assumptions!C11+Assumptions!C13+Assumptions!C12,tv,Assumptions!C14,REV2,R1*(1+GR2),REV3,REV2*(1+GR3),REV4,REV3*(1+GR4),REV5,REV4*(1+GR5),OP1,Assumptions!C28,OP2,OP1*(1+opgr),OP3,OP2*(1+opgr),OP4,OP3*(1+opgr),OP5,OP4*(1+opgr),pat,_xludf.LAMBDA(rev,opex,(rev*(1-cogs)-opex-da-intx)*(1-tax)+da),fcf_total,pat(R1,OP1)+pat(REV2,OP2)+pat(REV3,OP3)+pat(REV4,OP4)+pat(REV5,OP5)+tv,(fcf_total-inv)/inv) -> #NAME? | H17: =_xludf.LET(R1,2000000,GR2,0.35,GR3,Assumptions!C22,GR4,Assumptions!C23,GR5,Assumptions!C24,cogs,Assumptions!C27,opex1,Assumptions!C28,opgr,Assumptions!C29,da,Assumptions!C30,intx,Assumptions!C31,tax,Assumptions!C32,inv,Assumptions!C11+Assumptions!C13+Assumptions!C12,tv,Assumptions!C14,REV2,R1*(1+GR2),REV3,REV2*(1+GR3),REV4,REV3*(1+GR4),REV5,REV4*(1+GR5),OP1,Assumptions!C28,OP2,OP1*(1+opgr),OP3,OP2*(1+opgr),OP4,OP3*(1+opgr),OP5,OP4*(1+opgr),pat,_xludf.LAMBDA(rev,opex,(rev*(1-cogs)-opex-da-intx)*(1-tax)+da),fcf_total,pat(R1,OP1)+pat(REV2,OP2)+pat(REV3,OP3)+pat(REV4,OP4)+pat(REV5,OP5)+tv,(fcf_total-inv)/inv) -> #NAME?
B18: ₹25L | C18: =_xludf.LET(R1,2500000,GR2,0.1,GR3,Assumptions!C22,GR4,Assumptions!C23,GR5,Assumptions!C24,cogs,Assumptions!C27,opex1,Assumptions!C28,opgr,Assumptions!C29,da,Assumptions!C30,intx,Assumptions!C31,tax,Assumptions!C32,inv,Assumptions!C11+Assumptions!C13+Assumptions!C12,tv,Assumptions!C14,REV2,R1*(1+GR2),REV3,REV2*(1+GR3),REV4,REV3*(1+GR4),REV5,REV4*(1+GR5),OP1,Assumptions!C28,OP2,OP1*(1+opgr),OP3,OP2*(1+opgr),OP4,OP3*(1+opgr),OP5,OP4*(1+opgr),pat,_xludf.LAMBDA(rev,opex,(rev*(1-cogs)-opex-da-intx)*(1-tax)+da),fcf_total,pat(R1,OP1)+pat(REV2,OP2)+pat(REV3,OP3)+pat(REV4,OP4)+pat(REV5,OP5)+tv,(fcf_total-inv)/inv) -> #NAME? | D18: =_xludf.LET(R1,2500000,GR2,0.15,GR3,Assumptions!C22,GR4,Assumptions!C23,GR5,Assumptions!C24,cogs,Assumptions!C27,opex1,Assumptions!C28,opgr,Assumptions!C29,da,Assumptions!C30,intx,Assumptions!C31,tax,Assumptions!C32,inv,Assumptions!C11+Assumptions!C13+Assumptions!C12,tv,Assumptions!C14,REV2,R1*(1+GR2),REV3,REV2*(1+GR3),REV4,REV3*(1+GR4),REV5,REV4*(1+GR5),OP1,Assumptions!C28,OP2,OP1*(1+opgr),OP3,OP2*(1+opgr),OP4,OP3*(1+opgr),OP5,OP4*(1+opgr),pat,_xludf.LAMBDA(rev,opex,(rev*(1-cogs)-opex-da-intx)*(1-tax)+da),fcf_total,pat(R1,OP1)+pat(REV2,OP2)+pat(REV3,OP3)+pat(REV4,OP4)+pat(REV5,OP5)+tv,(fcf_total-inv)/inv) -> #NAME? | E18: =_xludf.LET(R1,2500000,GR2,0.2,GR3,Assumptions!C22,GR4,Assumptions!C23,GR5,Assumptions!C24,cogs,Assumptions!C27,opex1,Assumptions!C28,opgr,Assumptions!C29,da,Assumptions!C30,intx,Assumptions!C31,tax,Assumptions!C32,inv,Assumptions!C11+Assumptions!C13+Assumptions!C12,tv,Assumptions!C14,REV2,R1*(1+GR2),REV3,REV2*(1+GR3),REV4,REV3*(1+GR4),REV5,REV4*(1+GR5),OP1,Assumptions!C28,OP2,OP1*(1+opgr),OP3,OP2*(1+opgr),OP4,OP3*(1+opgr),OP5,OP4*(1+opgr),pat,_xludf.LAMBDA(rev,opex,(rev*(1-cogs)-opex-da-intx)*(1-tax)+da),fcf_total,pat(R1,OP1)+pat(REV2,OP2)+pat(REV3,OP3)+pat(REV4,OP4)+pat(REV5,OP5)+tv,(fcf_total-inv)/inv) -> #NAME? | F18: =_xludf.LET(R1,2500000,GR2,0.25,GR3,Assumptions!C22,GR4,Assumptions!C23,GR5,Assumptions!C24,cogs,Assumptions!C27,opex1,Assumptions!C28,opgr,Assumptions!C29,da,Assumptions!C30,intx,Assumptions!C31,tax,Assumptions!C32,inv,Assumptions!C11+Assumptions!C13+Assumptions!C12,tv,Assumptions!C14,REV2,R1*(1+GR2),REV3,REV2*(1+GR3),REV4,REV3*(1+GR4),REV5,REV4*(1+GR5),OP1,Assumptions!C28,OP2,OP1*(1+opgr),OP3,OP2*(1+opgr),OP4,OP3*(1+opgr),OP5,OP4*(1+opgr),pat,_xludf.LAMBDA(rev,opex,(rev*(1-cogs)-opex-da-intx)*(1-tax)+da),fcf_total,pat(R1,OP1)+pat(REV2,OP2)+pat(REV3,OP3)+pat(REV4,OP4)+pat(REV5,OP5)+tv,(fcf_total-inv)/inv) -> #NAME? | G18: =_xludf.LET(R1,2500000,GR2,0.3,GR3,Assumptions!C22,GR4,Assumptions!C23,GR5,Assumptions!C24,cogs,Assumptions!C27,opex1,Assumptions!C28,opgr,Assumptions!C29,da,Assumptions!C30,intx,Assumptions!C31,tax,Assumptions!C32,inv,Assumptions!C11+Assumptions!C13+Assumptions!C12,tv,Assumptions!C14,REV2,R1*(1+GR2),REV3,REV2*(1+GR3),REV4,REV3*(1+GR4),REV5,REV4*(1+GR5),OP1,Assumptions!C28,OP2,OP1*(1+opgr),OP3,OP2*(1+opgr),OP4,OP3*(1+opgr),OP5,OP4*(1+opgr),pat,_xludf.LAMBDA(rev,opex,(rev*(1-cogs)-opex-da-intx)*(1-tax)+da),fcf_total,pat(R1,OP1)+pat(REV2,OP2)+pat(REV3,OP3)+pat(REV4,OP4)+pat(REV5,OP5)+tv,(fcf_total-inv)/inv) -> #NAME? | H18: =_xludf.LET(R1,2500000,GR2,0.35,GR3,Assumptions!C22,GR4,Assumptions!C23,GR5,Assumptions!C24,cogs,Assumptions!C27,opex1,Assumptions!C28,opgr,Assumptions!C29,da,Assumptions!C30,intx,Assumptions!C31,tax,Assumptions!C32,inv,Assumptions!C11+Assumptions!C13+Assumptions!C12,tv,Assumptions!C14,REV2,R1*(1+GR2),REV3,REV2*(1+GR3),REV4,REV3*(1+GR4),REV5,REV4*(1+GR5),OP1,Assumptions!C28,OP2,OP1*(1+opgr),OP3,OP2*(1+opgr),OP4,OP3*(1+opgr),OP5,OP4*(1+opgr),pat,_xludf.LAMBDA(rev,opex,(rev*(1-cogs)-opex-da-intx)*(1-tax)+da),fcf_total,pat(R1,OP1)+pat(REV2,OP2)+pat(REV3,OP3)+pat(REV4,OP4)+pat(REV5,OP5)+tv,(fcf_total-inv)/inv) -> #NAME?
B19: ₹30L | C19: =_xludf.LET(R1,3000000,GR2,0.1,GR3,Assumptions!C22,GR4,Assumptions!C23,GR5,Assumptions!C24,cogs,Assumptions!C27,opex1,Assumptions!C28,opgr,Assumptions!C29,da,Assumptions!C30,intx,Assumptions!C31,tax,Assumptions!C32,inv,Assumptions!C11+Assumptions!C13+Assumptions!C12,tv,Assumptions!C14,REV2,R1*(1+GR2),REV3,REV2*(1+GR3),REV4,REV3*(1+GR4),REV5,REV4*(1+GR5),OP1,Assumptions!C28,OP2,OP1*(1+opgr),OP3,OP2*(1+opgr),OP4,OP3*(1+opgr),OP5,OP4*(1+opgr),pat,_xludf.LAMBDA(rev,opex,(rev*(1-cogs)-opex-da-intx)*(1-tax)+da),fcf_total,pat(R1,OP1)+pat(REV2,OP2)+pat(REV3,OP3)+pat(REV4,OP4)+pat(REV5,OP5)+tv,(fcf_total-inv)/inv) -> #NAME? | D19: =_xludf.LET(R1,3000000,GR2,0.15,GR3,Assumptions!C22,GR4,Assumptions!C23,GR5,Assumptions!C24,cogs,Assumptions!C27,opex1,Assumptions!C28,opgr,Assumptions!C29,da,Assumptions!C30,intx,Assumptions!C31,tax,Assumptions!C32,inv,Assumptions!C11+Assumptions!C13+Assumptions!C12,tv,Assumptions!C14,REV2,R1*(1+GR2),REV3,REV2*(1+GR3),REV4,REV3*(1+GR4),REV5,REV4*(1+GR5),OP1,Assumptions!C28,OP2,OP1*(1+opgr),OP3,OP2*(1+opgr),OP4,OP3*(1+opgr),OP5,OP4*(1+opgr),pat,_xludf.LAMBDA(rev,opex,(rev*(1-cogs)-opex-da-intx)*(1-tax)+da),fcf_total,pat(R1,OP1)+pat(REV2,OP2)+pat(REV3,OP3)+pat(REV4,OP4)+pat(REV5,OP5)+tv,(fcf_total-inv)/inv) -> #NAME? | E19: =_xludf.LET(R1,3000000,GR2,0.2,GR3,Assumptions!C22,GR4,Assumptions!C23,GR5,Assumptions!C24,cogs,Assumptions!C27,opex1,Assumptions!C28,opgr,Assumptions!C29,da,Assumptions!C30,intx,Assumptions!C31,tax,Assumptions!C32,inv,Assumptions!C11+Assumptions!C13+Assumptions!C12,tv,Assumptions!C14,REV2,R1*(1+GR2),REV3,REV2*(1+GR3),REV4,REV3*(1+GR4),REV5,REV4*(1+GR5),OP1,Assumptions!C28,OP2,OP1*(1+opgr),OP3,OP2*(1+opgr),OP4,OP3*(1+opgr),OP5,OP4*(1+opgr),pat,_xludf.LAMBDA(rev,opex,(rev*(1-cogs)-opex-da-intx)*(1-tax)+da),fcf_total,pat(R1,OP1)+pat(REV2,OP2)+pat(REV3,OP3)+pat(REV4,OP4)+pat(REV5,OP5)+tv,(fcf_total-inv)/inv) -> #NAME? | F19: =_xludf.LET(R1,3000000,GR2,0.25,GR3,Assumptions!C22,GR4,Assumptions!C23,GR5,Assumptions!C24,cogs,Assumptions!C27,opex1,Assumptions!C28,opgr,Assumptions!C29,da,Assumptions!C30,intx,Assumptions!C31,tax,Assumptions!C32,inv,Assumptions!C11+Assumptions!C13+Assumptions!C12,tv,Assumptions!C14,REV2,R1*(1+GR2),REV3,REV2*(1+GR3),REV4,REV3*(1+GR4),REV5,REV4*(1+GR5),OP1,Assumptions!C28,OP2,OP1*(1+opgr),OP3,OP2*(1+opgr),OP4,OP3*(1+opgr),OP5,OP4*(1+opgr),pat,_xludf.LAMBDA(rev,opex,(rev*(1-cogs)-opex-da-intx)*(1-tax)+da),fcf_total,pat(R1,OP1)+pat(REV2,OP2)+pat(REV3,OP3)+pat(REV4,OP4)+pat(REV5,OP5)+tv,(fcf_total-inv)/inv) -> #NAME? | G19: =_xludf.LET(R1,3000000,GR2,0.3,GR3,Assumptions!C22,GR4,Assumptions!C23,GR5,Assumptions!C24,cogs,Assumptions!C27,opex1,Assumptions!C28,opgr,Assumptions!C29,da,Assumptions!C30,intx,Assumptions!C31,tax,Assumptions!C32,inv,Assumptions!C11+Assumptions!C13+Assumptions!C12,tv,Assumptions!C14,REV2,R1*(1+GR2),REV3,REV2*(1+GR3),REV4,REV3*(1+GR4),REV5,REV4*(1+GR5),OP1,Assumptions!C28,OP2,OP1*(1+opgr),OP3,OP2*(1+opgr),OP4,OP3*(1+opgr),OP5,OP4*(1+opgr),pat,_xludf.LAMBDA(rev,opex,(rev*(1-cogs)-opex-da-intx)*(1-tax)+da),fcf_total,pat(R1,OP1)+pat(REV2,OP2)+pat(REV3,OP3)+pat(REV4,OP4)+pat(REV5,OP5)+tv,(fcf_total-inv)/inv) -> #NAME? | H19: =_xludf.LET(R1,3000000,GR2,0.35,GR3,Assumptions!C22,GR4,Assumptions!C23,GR5,Assumptions!C24,cogs,Assumptions!C27,opex1,Assumptions!C28,opgr,Assumptions!C29,da,Assumptions!C30,intx,Assumptions!C31,tax,Assumptions!C32,inv,Assumptions!C11+Assumptions!C13+Assumptions!C12,tv,Assumptions!C14,REV2,R1*(1+GR2),REV3,REV2*(1+GR3),REV4,REV3*(1+GR4),REV5,REV4*(1+GR5),OP1,Assumptions!C28,OP2,OP1*(1+opgr),OP3,OP2*(1+opgr),OP4,OP3*(1+opgr),OP5,OP4*(1+opgr),pat,_xludf.LAMBDA(rev,opex,(rev*(1-cogs)-opex-da-intx)*(1-tax)+da),fcf_total,pat(R1,OP1)+pat(REV2,OP2)+pat(REV3,OP3)+pat(REV4,OP4)+pat(REV5,OP5)+tv,(fcf_total-inv)/inv) -> #NAME?
B20: ₹35L | C20: =_xludf.LET(R1,3500000,GR2,0.1,GR3,Assumptions!C22,GR4,Assumptions!C23,GR5,Assumptions!C24,cogs,Assumptions!C27,opex1,Assumptions!C28,opgr,Assumptions!C29,da,Assumptions!C30,intx,Assumptions!C31,tax,Assumptions!C32,inv,Assumptions!C11+Assumptions!C13+Assumptions!C12,tv,Assumptions!C14,REV2,R1*(1+GR2),REV3,REV2*(1+GR3),REV4,REV3*(1+GR4),REV5,REV4*(1+GR5),OP1,Assumptions!C28,OP2,OP1*(1+opgr),OP3,OP2*(1+opgr),OP4,OP3*(1+opgr),OP5,OP4*(1+opgr),pat,_xludf.LAMBDA(rev,opex,(rev*(1-cogs)-opex-da-intx)*(1-tax)+da),fcf_total,pat(R1,OP1)+pat(REV2,OP2)+pat(REV3,OP3)+pat(REV4,OP4)+pat(REV5,OP5)+tv,(fcf_total-inv)/inv) -> #NAME? | D20: =_xludf.LET(R1,3500000,GR2,0.15,GR3,Assumptions!C22,GR4,Assumptions!C23,GR5,Assumptions!C24,cogs,Assumptions!C27,opex1,Assumptions!C28,opgr,Assumptions!C29,da,Assumptions!C30,intx,Assumptions!C31,tax,Assumptions!C32,inv,Assumptions!C11+Assumptions!C13+Assumptions!C12,tv,Assumptions!C14,REV2,R1*(1+GR2),REV3,REV2*(1+GR3),REV4,REV3*(1+GR4),REV5,REV4*(1+GR5),OP1,Assumptions!C28,OP2,OP1*(1+opgr),OP3,OP2*(1+opgr),OP4,OP3*(1+opgr),OP5,OP4*(1+opgr),pat,_xludf.LAMBDA(rev,opex,(rev*(1-cogs)-opex-da-intx)*(1-tax)+da),fcf_total,pat(R1,OP1)+pat(REV2,OP2)+pat(REV3,OP3)+pat(REV4,OP4)+pat(REV5,OP5)+tv,(fcf_total-inv)/inv) -> #NAME? | E20: =_xludf.LET(R1,3500000,GR2,0.2,GR3,Assumptions!C22,GR4,Assumptions!C23,GR5,Assumptions!C24,cogs,Assumptions!C27,opex1,Assumptions!C28,opgr,Assumptions!C29,da,Assumptions!C30,intx,Assumptions!C31,tax,Assumptions!C32,inv,Assumptions!C11+Assumptions!C13+Assumptions!C12,tv,Assumptions!C14,REV2,R1*(1+GR2),REV3,REV2*(1+GR3),REV4,REV3*(1+GR4),REV5,REV4*(1+GR5),OP1,Assumptions!C28,OP2,OP1*(1+opgr),OP3,OP2*(1+opgr),OP4,OP3*(1+opgr),OP5,OP4*(1+opgr),pat,_xludf.LAMBDA(rev,opex,(rev*(1-cogs)-opex-da-intx)*(1-tax)+da),fcf_total,pat(R1,OP1)+pat(REV2,OP2)+pat(REV3,OP3)+pat(REV4,OP4)+pat(REV5,OP5)+tv,(fcf_total-inv)/inv) -> #NAME? | F20: =_xludf.LET(R1,3500000,GR2,0.25,GR3,Assumptions!C22,GR4,Assumptions!C23,GR5,Assumptions!C24,cogs,Assumptions!C27,opex1,Assumptions!C28,opgr,Assumptions!C29,da,Assumptions!C30,intx,Assumptions!C31,tax,Assumptions!C32,inv,Assumptions!C11+Assumptions!C13+Assumptions!C12,tv,Assumptions!C14,REV2,R1*(1+GR2),REV3,REV2*(1+GR3),REV4,REV3*(1+GR4),REV5,REV4*(1+GR5),OP1,Assumptions!C28,OP2,OP1*(1+opgr),OP3,OP2*(1+opgr),OP4,OP3*(1+opgr),OP5,OP4*(1+opgr),pat,_xludf.LAMBDA(rev,opex,(rev*(1-cogs)-opex-da-intx)*(1-tax)+da),fcf_total,pat(R1,OP1)+pat(REV2,OP2)+pat(REV3,OP3)+pat(REV4,OP4)+pat(REV5,OP5)+tv,(fcf_total-inv)/inv) -> #NAME? | G20: =_xludf.LET(R1,3500000,GR2,0.3,GR3,Assumptions!C22,GR4,Assumptions!C23,GR5,Assumptions!C24,cogs,Assumptions!C27,opex1,Assumptions!C28,opgr,Assumptions!C29,da,Assumptions!C30,intx,Assumptions!C31,tax,Assumptions!C32,inv,Assumptions!C11+Assumptions!C13+Assumptions!C12,tv,Assumptions!C14,REV2,R1*(1+GR2),REV3,REV2*(1+GR3),REV4,REV3*(1+GR4),REV5,REV4*(1+GR5),OP1,Assumptions!C28,OP2,OP1*(1+opgr),OP3,OP2*(1+opgr),OP4,OP3*(1+opgr),OP5,OP4*(1+opgr),pat,_xludf.LAMBDA(rev,opex,(rev*(1-cogs)-opex-da-intx)*(1-tax)+da),fcf_total,pat(R1,OP1)+pat(REV2,OP2)+pat(REV3,OP3)+pat(REV4,OP4)+pat(REV5,OP5)+tv,(fcf_total-inv)/inv) -> #NAME? | H20: =_xludf.LET(R1,3500000,GR2,0.35,GR3,Assumptions!C22,GR4,Assumptions!C23,GR5,Assumptions!C24,cogs,Assumptions!C27,opex1,Assumptions!C28,opgr,Assumptions!C29,da,Assumptions!C30,intx,Assumptions!C31,tax,Assumptions!C32,inv,Assumptions!C11+Assumptions!C13+Assumptions!C12,tv,Assumptions!C14,REV2,R1*(1+GR2),REV3,REV2*(1+GR3),REV4,REV3*(1+GR4),REV5,REV4*(1+GR5),OP1,Assumptions!C28,OP2,OP1*(1+opgr),OP3,OP2*(1+opgr),OP4,OP3*(1+opgr),OP5,OP4*(1+opgr),pat,_xludf.LAMBDA(rev,opex,(rev*(1-cogs)-opex-da-intx)*(1-tax)+da),fcf_total,pat(R1,OP1)+pat(REV2,OP2)+pat(REV3,OP3)+pat(REV4,OP4)+pat(REV5,OP5)+tv,(fcf_total-inv)/inv) -> #NAME?
B21: ₹40L | C21: =_xludf.LET(R1,4000000,GR2,0.1,GR3,Assumptions!C22,GR4,Assumptions!C23,GR5,Assumptions!C24,cogs,Assumptions!C27,opex1,Assumptions!C28,opgr,Assumptions!C29,da,Assumptions!C30,intx,Assumptions!C31,tax,Assumptions!C32,inv,Assumptions!C11+Assumptions!C13+Assumptions!C12,tv,Assumptions!C14,REV2,R1*(1+GR2),REV3,REV2*(1+GR3),REV4,REV3*(1+GR4),REV5,REV4*(1+GR5),OP1,Assumptions!C28,OP2,OP1*(1+opgr),OP3,OP2*(1+opgr),OP4,OP3*(1+opgr),OP5,OP4*(1+opgr),pat,_xludf.LAMBDA(rev,opex,(rev*(1-cogs)-opex-da-intx)*(1-tax)+da),fcf_total,pat(R1,OP1)+pat(REV2,OP2)+pat(REV3,OP3)+pat(REV4,OP4)+pat(REV5,OP5)+tv,(fcf_total-inv)/inv) -> #NAME? | D21: =_xludf.LET(R1,4000000,GR2,0.15,GR3,Assumptions!C22,GR4,Assumptions!C23,GR5,Assumptions!C24,cogs,Assumptions!C27,opex1,Assumptions!C28,opgr,Assumptions!C29,da,Assumptions!C30,intx,Assumptions!C31,tax,Assumptions!C32,inv,Assumptions!C11+Assumptions!C13+Assumptions!C12,tv,Assumptions!C14,REV2,R1*(1+GR2),REV3,REV2*(1+GR3),REV4,REV3*(1+GR4),REV5,REV4*(1+GR5),OP1,Assumptions!C28,OP2,OP1*(1+opgr),OP3,OP2*(1+opgr),OP4,OP3*(1+opgr),OP5,OP4*(1+opgr),pat,_xludf.LAMBDA(rev,opex,(rev*(1-cogs)-opex-da-intx)*(1-tax)+da),fcf_total,pat(R1,OP1)+pat(REV2,OP2)+pat(REV3,OP3)+pat(REV4,OP4)+pat(REV5,OP5)+tv,(fcf_total-inv)/inv) -> #NAME? | E21: =_xludf.LET(R1,4000000,GR2,0.2,GR3,Assumptions!C22,GR4,Assumptions!C23,GR5,Assumptions!C24,cogs,Assumptions!C27,opex1,Assumptions!C28,opgr,Assumptions!C29,da,Assumptions!C30,intx,Assumptions!C31,tax,Assumptions!C32,inv,Assumptions!C11+Assumptions!C13+Assumptions!C12,tv,Assumptions!C14,REV2,R1*(1+GR2),REV3,REV2*(1+GR3),REV4,REV3*(1+GR4),REV5,REV4*(1+GR5),OP1,Assumptions!C28,OP2,OP1*(1+opgr),OP3,OP2*(1+opgr),OP4,OP3*(1+opgr),OP5,OP4*(1+opgr),pat,_xludf.LAMBDA(rev,opex,(rev*(1-cogs)-opex-da-intx)*(1-tax)+da),fcf_total,pat(R1,OP1)+pat(REV2,OP2)+pat(REV3,OP3)+pat(REV4,OP4)+pat(REV5,OP5)+tv,(fcf_total-inv)/inv) -> #NAME? | F21: =_xludf.LET(R1,4000000,GR2,0.25,GR3,Assumptions!C22,GR4,Assumptions!C23,GR5,Assumptions!C24,cogs,Assumptions!C27,opex1,Assumptions!C28,opgr,Assumptions!C29,da,Assumptions!C30,intx,Assumptions!C31,tax,Assumptions!C32,inv,Assumptions!C11+Assumptions!C13+Assumptions!C12,tv,Assumptions!C14,REV2,R1*(1+GR2),REV3,REV2*(1+GR3),REV4,REV3*(1+GR4),REV5,REV4*(1+GR5),OP1,Assumptions!C28,OP2,OP1*(1+opgr),OP3,OP2*(1+opgr),OP4,OP3*(1+opgr),OP5,OP4*(1+opgr),pat,_xludf.LAMBDA(rev,opex,(rev*(1-cogs)-opex-da-intx)*(1-tax)+da),fcf_total,pat(R1,OP1)+pat(REV2,OP2)+pat(REV3,OP3)+pat(REV4,OP4)+pat(REV5,OP5)+tv,(fcf_total-inv)/inv) -> #NAME? | G21: =_xludf.LET(R1,4000000,GR2,0.3,GR3,Assumptions!C22,GR4,Assumptions!C23,GR5,Assumptions!C24,cogs,Assumptions!C27,opex1,Assumptions!C28,opgr,Assumptions!C29,da,Assumptions!C30,intx,Assumptions!C31,tax,Assumptions!C32,inv,Assumptions!C11+Assumptions!C13+Assumptions!C12,tv,Assumptions!C14,REV2,R1*(1+GR2),REV3,REV2*(1+GR3),REV4,REV3*(1+GR4),REV5,REV4*(1+GR5),OP1,Assumptions!C28,OP2,OP1*(1+opgr),OP3,OP2*(1+opgr),OP4,OP3*(1+opgr),OP5,OP4*(1+opgr),pat,_xludf.LAMBDA(rev,opex,(rev*(1-cogs)-opex-da-intx)*(1-tax)+da),fcf_total,pat(R1,OP1)+pat(REV2,OP2)+pat(REV3,OP3)+pat(REV4,OP4)+pat(REV5,OP5)+tv,(fcf_total-inv)/inv) -> #NAME? | H21: =_xludf.LET(R1,4000000,GR2,0.35,GR3,Assumptions!C22,GR4,Assumptions!C23,GR5,Assumptions!C24,cogs,Assumptions!C27,opex1,Assumptions!C28,opgr,Assumptions!C29,da,Assumptions!C30,intx,Assumptions!C31,tax,Assumptions!C32,inv,Assumptions!C11+Assumptions!C13+Assumptions!C12,tv,Assumptions!C14,REV2,R1*(1+GR2),REV3,REV2*(1+GR3),REV4,REV3*(1+GR4),REV5,REV4*(1+GR5),OP1,Assumptions!C28,OP2,OP1*(1+opgr),OP3,OP2*(1+opgr),OP4,OP3*(1+opgr),OP5,OP4*(1+opgr),pat,_xludf.LAMBDA(rev,opex,(rev*(1-cogs)-opex-da-intx)*(1-tax)+da),fcf_total,pat(R1,OP1)+pat(REV2,OP2)+pat(REV3,OP3)+pat(REV4,OP4)+pat(REV5,OP5)+tv,(fcf_total-inv)/inv) -> #NAME?
